Workbook

Sheet Bar Chart Medians
A2: Mobility in First Twenty-Five Time Steps (# Out) | G2: Cumulative Cases | M2: Largest Peak in Cases | S2: Epidemic Duration
B3: Base Run | C3: Symptom Information | D3: Full Feedback | H3: Base Run | I3: Symptom Information | J3: Full Feedback | N3: Base Run | O3: Symptom Information | P3: Full Feedback | T3: Base Run | U3: Symptom Information | V3: Full Feedback
A4: Median | B4: ='# Out NF'!O38 -> 0.99992 | C4: ='# Out SF'!O46 -> 0.8781 | D4: ='# Out FF'!O209 -> 0.71816 | G4: Median | H4: ='New Infections NF'!B44 -> 998 | I4: ='New Infections SF'!B52 -> 775 | J4: ='New Infections FF'!B218 -> 377 | M4: Median | N4: ='New Infections NF'!B40 -> 189.5 | O4: ='New Infections SF'!B48 -> 94.5 | P4: ='New Infections FF'!B214 -> 20 | S4: Median | T4: =MEDIAN('# Out NF'!B37:K37) -> 24 | U4: 30.5 | V4: 87
A5: 10% Run | B5: ='# Out NF'!O39 -> 0.99872 | C5: ='# Out SF'!O47 -> 0.87388 | D5: ='# Out FF'!O210 -> 0.69932 | G5: 10% Run | H5: ='New Infections NF'!B45 -> 997 | I5: ='New Infections SF'!B53 -> 761 | J5: ='New Infections FF'!B219 -> 345 | M5: 10% Run | N5: ='New Infections NF'!B41 -> 178 | O5: ='New Infections SF'!B49 -> 87 | P5: ='New Infections FF'!B215 -> 17 | S5: 10% Run | T5: 22 | U5: 26 | V5: 75
A6: 90%Run | B6: ='# Out NF'!O40 -> 1 | C6: ='# Out SF'!O48 -> 0.87976 | D6: ='# Out FF'!O211 -> 0.73884 | G6: 90%Run | H6: ='New Infections NF'!B46 -> 999 | I6: ='New Infections SF'!B54 -> 793 | J6: ='New Infections FF'!B220 -> 478 | M6: 90%Run | N6: ='New Infections NF'!B42 -> 198 | O6: ='New Infections SF'!B50 -> 104 | P6: ='New Infections FF'!B216 -> 29 | S6: 90%Run | T6: 25 | U6: 33 | V6: 123
A8: Diff10% | B8: =B4-B5 -> 0.0012 | C8: =C4-C5 -> 0.00422 | D8: =D4-D5 -> 0.01884 | G8: Diff10% | H8: =H4-H5 -> 1 | I8: =I4-I5 -> 14 | J8: =J4-J5 -> 32 | M8: Diff10% | N8: =N4-N5 -> 11.5 | O8: =O4-O5 -> 7.5 | P8: =P4-P5 -> 3 | S8: Diff10% | T8: =T4-T5 -> 2 | U8: =U4-U5 -> 4.5 | V8: =V4-V5 -> 12
A9: Diff90% | B9: =B6-B4 -> 8e-05 | C9: =C6-C4 -> 0.00166 | D9: =D6-D4 -> 0.02068 | G9: Diff90% | H9: =H6-H4 -> 1 | I9: =I6-I4 -> 18 | J9: =J6-J4 -> 101 | M9: Diff90% | N9: =N6-N4 -> 8.5 | O9: =O6-O4 -> 9.5 | P9: =P6-P4 -> 9 | S9: Diff90% | T9: =T6-T4 -> 1 | U9: =U6-U4 -> 2.5 | V9: =V6-V4 -> 36

Sheet GraphsTime
AD1: Cumullative Sums | AE1: Base Run | AF1: Symptom Information | AG1: Full Feedback
AE2: ='New Infections NF'!N3 -> 2 | AF2: ='New Infections SF'!N3 -> 2 | AG2: ='New Infections FF'!N3 -> 2
AE3: ='New Infections NF'!N4 -> 4.1 | AF3: ='New Infections SF'!N4 -> 4 | AG3: ='New Infections FF'!N4 -> 4.2
AE4: ='New Infections NF'!N5 -> 7.8 | AF4: ='New Infections SF'!N5 -> 8.5 | AG4: ='New Infections FF'!N5 -> 8.4
AE5: ='New Infections NF'!N6 -> 15 | AF5: ='New Infections SF'!N6 -> 15 | AG5: ='New Infections FF'!N6 -> 15.3
AE6: ='New Infections NF'!N7 -> 30.3 | AF6: ='New Infections SF'!N7 -> 23.8 | AG6: ='New Infections FF'!N7 -> 22.5
AE7: ='New Infections NF'!N8 -> 57.6 | AF7: ='New Infections SF'!N8 -> 38.6 | AG7: ='New Infections FF'!N8 -> 32
AE8: ='New Infections NF'!N9 -> 112.2 | AF8: ='New Infections SF'!N9 -> 60.1 | AG8: ='New Infections FF'!N9 -> 41.9
AE9: ='New Infections NF'!N10 -> 196.5 | AF9: ='New Infections SF'!N10 -> 93.7 | AG9: ='New Infections FF'!N10 -> 52.8
AE10: ='New Infections NF'!N11 -> 329 | AF10: ='New Infections SF'!N11 -> 136.4 | AG10: ='New Infections FF'!N11 -> 62.7
AE11: ='New Infections NF'!N12 -> 504.4 | AF11: ='New Infections SF'!N12 -> 193.6 | AG11: ='New Infections FF'!N12 -> 71.9
AE12: ='New Infections NF'!N13 -> 686 | AF12: ='New Infections SF'!N13 -> 261.1 | AG12: ='New Infections FF'!N13 -> 82.8
AE13: ='New Infections NF'!N14 -> 832.6 | AF13: ='New Infections SF'!N14 -> 336.9 | AG13: ='New Infections FF'!N14 -> 92.1
... AE22: ='New Infections NF'!N23 -> 997.6 | AF22: ='New Infections SF'!N23 -> 693.3 | AG22: ='New Infections FF'!N23 -> 153.2
AF23: ='New Infections SF'!N24 -> 696.4 | AG23: ='New Infections FF'!N24 -> 159
AF24: ='New Infections SF'!N25 -> 698.5 | AG24: ='New Infections FF'!N25 -> 165.3
AF25: ='New Infections SF'!N26 -> 699.7 | AG25: ='New Infections FF'!N26 -> 170.2
AF26: ='New Infections SF'!N27 -> 700.5 | AG26: ='New Infections FF'!N27 -> 175.6
AF27: ='New Infections SF'!N28 -> 701 | AG27: ='New Infections FF'!N28 -> 183.3
AF28: ='New Infections SF'!N29 -> 701.2 | AG28: ='New Infections FF'!N29 -> 190.3
AF29: ='New Infections SF'!N30 -> 701.3 | AG29: ='New Infections FF'!N30 -> 198.1
AF30: ='New Infections SF'!N31 -> 701.4 | AG30: ='New Infections FF'!N31 -> 205.9
AF31: ='New Infections SF'!N32 -> 701.4 | AG31: ='New Infections FF'!N32 -> 212.9
AF32: ='New Infections SF'!N33 -> 701.4 | AG32: ='New Infections FF'!N33 -> 218.4
AF33: ='New Infections SF'!N34 -> 701.4 | AG33: ='New Infections FF'!N34 -> 221.9
AF34: ='New Infections SF'!N35 -> 701.4 | AG34: ='New Infections FF'!N35 -> 226.5
... AF36: ='New Infections SF'!N37 -> 701.4 | AG36: ='New Infections FF'!N37 -> 234.5
AG37: ='New Infections FF'!N38 -> 239.5
AG38: ='New Infections FF'!N39 -> 243.9
AG39: ='New Infections FF'!N40 -> 246.9
AG40: ='New Infections FF'!N41 -> 252
AG41: ='New Infections FF'!N42 -> 255.4
AG42: ='New Infections FF'!N43 -> 260.2
AG43: ='New Infections FF'!N44 -> 264.1
AG44: ='New Infections FF'!N45 -> 267.8
AG45: ='New Infections FF'!N46 -> 271.9
AG46: ='New Infections FF'!N47 -> 275.4
AG47: ='New Infections FF'!N48 -> 279.6
AG48: ='New Infections FF'!N49 -> 283.7
... AG199: ='New Infections FF'!N200 -> 381.7

Sheet Bar Graphs Means
B1: Base Run | C1: Symptom Information | D1: Full Feedback | O1: Base Run | P1: Symptom Information | Q1: Full Feedback | AF1: Base Run | AG1: Symptom Information | AH1: Full Feedback
B2: ='# Out NF'!O33 -> 0.999456 | C2: ='# Out SF'!O41 -> 0.889028 | D2: ='# Out FF'!O204 -> 0.716656 | N2: Average of Average for 25ts | O2: 997.6 | P2: 701.4 | Q2: 381.7 | Y2: Largest Peak in Cases | AD2: Epidemic Duration | AE2: Average | AF2: ='# Out NF'!D34-1 -> 23.9 | AG2: ='# Out SF'!D44-1 -> 28 | AH2: ='DNC4 FF'!F212-1 -> 98.5
B3: ='# Out NF'!O34 -> 0.99796 | C3: ='# Out SF'!O42 -> 0.87044 | D3: ='# Out FF'!O205 -> 0.6516 | F3: =B2-B3 -> 0.001496 | G3: =C2-C3 -> 0.018588 | H3: =D2-D3 -> 0.065056 | N3: Min run | O3: 993 | P3: 2 | Q3: 236 | S3: =O2-O3 -> 4.6 | T3: =P2-P3 -> 699.4 | U3: =Q2-Q3 -> 145.7 | AE3: Min | AF3: =23-1 -> 22 | AG3: =7-1 -> 6 | AH3: =54-1 -> 53 | AJ3: =AF2-AF3 -> 1.9 | AK3: =AG2-AG3 -> 22 | AL3: =AH2-AH3 -> 45.5
B4: ='# Out NF'!O35 -> 1 | C4: ='# Out SF'!O43 -> 0.99968 | D4: ='# Out FF'!O206 -> 0.75092 | F4: =B4-B2 -> 0.000544 | G4: =C4-C2 -> 0.110652 | H4: =D4-D2 -> 0.034264 | N4: Max run | O4: 1000 | P4: 812 | Q4: 503 | S4: =O4-O2 -> 2.4 | T4: =P4-P2 -> 110.6 | U4: =Q4-Q2 -> 121.3 | Z4: Base Run | AA4: Symptom Information | AB4: Full Feedback | AE4: Max | AF4: =27-1 -> 26 | AG4: =35-1 -> 34 | AH4: =198-1 -> 197 | AJ4: =AF4-AF2 -> 2.1 | AK4: =AG4-AG2 -> 6 | AL4: =AH4-AH2 -> 98.5
Y5: ='# Out NF'!N33 -> Average of Average for 25ts | Z5: ='New Infections NF'!P2 -> 202 | AA5: ='New Infections SF'!Q3 -> 114 | AB5: ='New Infections FF'!Q3 -> 34
U19: median peak, 80% CI
AE26: BAR without top 10 and low 10. so drop 2 runs for bar
M27: BAR without top 10 and low 10. so drop 2 runs for bar
Z41: Redo average of largest peaks

Sheet Mobility Curve FF
A1: ='DNC4 FF'!A1 -> DNC4 per timestep | N1: ='# Out NF'!A1 -> # Out per timestep | AB1: Mobility Curve Data
A2: ='DNC4 FF'!A2 -> Time Step | B2: ='DNC4 FF'!B2 -> Run 1 | C2: ='DNC4 FF'!C2 -> Run 2 | D2: ='DNC4 FF'!D2 -> Run 3 | E2: ='DNC4 FF'!E2 -> Run 4 | F2: ='DNC4 FF'!F2 -> Run 5 | G2: ='DNC4 FF'!G2 -> Run 6 | H2: ='DNC4 FF'!H2 -> Run 7 | ... L2: ='DNC4 FF'!L2 -> Average | N2: ='# Out FF'!A2 -> Time Step | O2: ='# Out FF'!B2 -> Run 1 | P2: ='# Out FF'!C2 -> Run 2 | Q2: ='# Out FF'!D2 -> Run 3 | R2: ='# Out FF'!E2 -> Run 4 | S2: ='# Out FF'!F2 -> Run 5 | T2: ='# Out FF'!G2 -> Run 6 | U2: ='# Out FF'!H2 -> Run 7 | ... Y2: ='# Out FF'!L2 -> Average | AB2: DNC | AC2: Out | AF2: % New Active Cases | AG2: Mobility | AH2: Best Fit Exp Line | AI2: Residuals
A3: ='DNC4 FF'!A3 -> 0 | B3: ='DNC4 FF'!B3 -> 0 | C3: ='DNC4 FF'!C3 -> 0 | D3: ='DNC4 FF'!D3 -> 0 | E3: ='DNC4 FF'!E3 -> 0 | F3: ='DNC4 FF'!F3 -> 0 | G3: ='DNC4 FF'!G3 -> 0 | H3: ='DNC4 FF'!H3 -> 0 | ... L3: ='DNC4 FF'!L3 -> 0 | N3: ='# Out FF'!A3 -> 0 | O3: ='# Out FF'!B3 -> 1000 | P3: ='# Out FF'!C3 -> 1000 | Q3: ='# Out FF'!D3 -> 1000 | R3: ='# Out FF'!E3 -> 1000 | S3: ='# Out FF'!F3 -> 1000 | T3: ='# Out FF'!G3 -> 1000 | U3: ='# Out FF'!H3 -> 1000 | ... Y3: ='# Out FF'!L3 -> 1000 | AB3: {=B3:B78} -> 0 | AC3: {=O4:O79} -> 998 | AF3: =AB3/1000 -> 0 | AG3: =AC3/1000 -> 0.998 | AH3: =0.891*EXP(-40.26*AF3) -> 0.891 | AI3: =AG3-AH3 -> 0.107
A4: ='DNC4 FF'!A4 -> 1 | B4: ='DNC4 FF'!B4 -> 0 | C4: ='DNC4 FF'!C4 -> 0 | D4: ='DNC4 FF'!D4 -> 0 | E4: ='DNC4 FF'!E4 -> 0 | F4: ='DNC4 FF'!F4 -> 0 | G4: ='DNC4 FF'!G4 -> 0 | H4: ='DNC4 FF'!H4 -> 0 | ... L4: ='DNC4 FF'!L4 -> 0 | N4: ='# Out FF'!A4 -> 1 | O4: ='# Out FF'!B4 -> 998 | P4: ='# Out FF'!C4 -> 996 | Q4: ='# Out FF'!D4 -> 995 | R4: ='# Out FF'!E4 -> 998 | S4: ='# Out FF'!F4 -> 997 | T4: ='# Out FF'!G4 -> 997 | U4: ='# Out FF'!H4 -> 995 | ... Y4: ='# Out FF'!L4 -> 996.9 | AB4: 0 | AC4: 997 | AF4: =AB4/1000 -> 0 | AG4: =AC4/1000 -> 0.997 | AH4: =0.891*EXP(-40.26*AF4) -> 0.891 | AI4: =AG4-AH4 -> 0.106
A5: ='DNC4 FF'!A5 -> 2 | B5: ='DNC4 FF'!B5 -> 0 | C5: ='DNC4 FF'!C5 -> 0 | D5: ='DNC4 FF'!D5 -> 0 | E5: ='DNC4 FF'!E5 -> 0 | F5: ='DNC4 FF'!F5 -> 0 | G5: ='DNC4 FF'!G5 -> 0 | H5: ='DNC4 FF'!H5 -> 0 | ... L5: ='DNC4 FF'!L5 -> 0 | N5: ='# Out FF'!A5 -> 2 | O5: ='# Out FF'!B5 -> 997 | P5: ='# Out FF'!C5 -> 996 | Q5: ='# Out FF'!D5 -> 994 | R5: ='# Out FF'!E5 -> 999 | S5: ='# Out FF'!F5 -> 998 | T5: ='# Out FF'!G5 -> 997 | U5: ='# Out FF'!H5 -> 997 | ... Y5: ='# Out FF'!L5 -> 997.2 | AB5: 0 | AC5: 999 | AF5: =AB5/1000 -> 0 | AG5: =AC5/1000 -> 0.999 | AH5: =0.891*EXP(-40.26*AF5) -> 0.891 | AI5: =AG5-AH5 -> 0.108
A6: ='DNC4 FF'!A6 -> 3 | B6: ='DNC4 FF'!B6 -> 2 | C6: ='DNC4 FF'!C6 -> 2 | D6: ='DNC4 FF'!D6 -> 2 | E6: ='DNC4 FF'!E6 -> 2 | F6: ='DNC4 FF'!F6 -> 2 | G6: ='DNC4 FF'!G6 -> 2 | H6: ='DNC4 FF'!H6 -> 2 | ... L6: ='DNC4 FF'!L6 -> 2 | N6: ='# Out FF'!A6 -> 3 | O6: ='# Out FF'!B6 -> 999 | P6: ='# Out FF'!C6 -> 998 | Q6: ='# Out FF'!D6 -> 994 | R6: ='# Out FF'!E6 -> 999 | S6: ='# Out FF'!F6 -> 996 | T6: ='# Out FF'!G6 -> 997 | U6: ='# Out FF'!H6 -> 997 | ... Y6: ='# Out FF'!L6 -> 997.3 | AB6: 2 | AC6: 782 | AF6: =AB6/1000 -> 0.002 | AG6: =AC6/1000 -> 0.782 | AH6: =0.891*EXP(-40.26*AF6) -> 0.82206908 | AI6: =AG6-AH6 -> -0.040069078
A7: ='DNC4 FF'!A7 -> 4 | B7: ='DNC4 FF'!B7 -> 3 | C7: ='DNC4 FF'!C7 -> 1 | D7: ='DNC4 FF'!D7 -> 4 | E7: ='DNC4 FF'!E7 -> 0 | F7: ='DNC4 FF'!F7 -> 2 | G7: ='DNC4 FF'!G7 -> 0 | H7: ='DNC4 FF'!H7 -> 1 | ... L7: ='DNC4 FF'!L7 -> 2.2 | N7: ='# Out FF'!A7 -> 4 | O7: ='# Out FF'!B7 -> 782 | P7: ='# Out FF'!C7 -> 796 | Q7: ='# Out FF'!D7 -> 775 | R7: ='# Out FF'!E7 -> 791 | S7: ='# Out FF'!F7 -> 787 | T7: ='# Out FF'!G7 -> 793 | U7: ='# Out FF'!H7 -> 775 | ... Y7: ='# Out FF'!L7 -> 785.4 | AB7: 3 | AC7: 771 | AF7: =AB7/1000 -> 0.003 | AG7: =AC7/1000 -> 0.771 | AH7: =0.891*EXP(-40.26*AF7) -> 0.78962996 | AI7: =AG7-AH7 -> -0.018629957
A8: ='DNC4 FF'!A8 -> 5 | B8: ='DNC4 FF'!B8 -> 9 | C8: ='DNC4 FF'!C8 -> 4 | D8: ='DNC4 FF'!D8 -> 5 | E8: ='DNC4 FF'!E8 -> 3 | F8: ='DNC4 FF'!F8 -> 5 | G8: ='DNC4 FF'!G8 -> 2 | H8: ='DNC4 FF'!H8 -> 2 | ... L8: ='DNC4 FF'!L8 -> 4.2 | N8: ='# Out FF'!A8 -> 5 | O8: ='# Out FF'!B8 -> 771 | P8: ='# Out FF'!C8 -> 807 | Q8: ='# Out FF'!D8 -> 786 | R8: ='# Out FF'!E8 -> 995 | S8: ='# Out FF'!F8 -> 794 | T8: ='# Out FF'!G8 -> 995 | U8: ='# Out FF'!H8 -> 803 | ... Y8: ='# Out FF'!L8 -> 805.5 | AB8: 9 | AC8: 710 | AF8: =AB8/1000 -> 0.009 | AG8: =AC8/1000 -> 0.71 | AH8: =0.891*EXP(-40.26*AF8) -> 0.62017669 | AI8: =AG8-AH8 -> 0.089823306
A9: ='DNC4 FF'!A9 -> 6 | B9: ='DNC4 FF'!B9 -> 8 | C9: ='DNC4 FF'!C9 -> 10 | D9: ='DNC4 FF'!D9 -> 9 | E9: ='DNC4 FF'!E9 -> 8 | F9: ='DNC4 FF'!F9 -> 6 | G9: ='DNC4 FF'!G9 -> 2 | H9: ='DNC4 FF'!H9 -> 5 | ... L9: ='DNC4 FF'!L9 -> 6.9 | N9: ='# Out FF'!A9 -> 6 | O9: ='# Out FF'!B9 -> 710 | P9: ='# Out FF'!C9 -> 795 | Q9: ='# Out FF'!D9 -> 532 | R9: ='# Out FF'!E9 -> 766 | S9: ='# Out FF'!F9 -> 533 | T9: ='# Out FF'!G9 -> 802 | U9: ='# Out FF'!H9 -> 772 | ... Y9: ='# Out FF'!L9 -> 720.9 | AB9: 8 | AC9: 658 | AF9: =AB9/1000 -> 0.008 | AG9: =AC9/1000 -> 0.658 | AH9: =0.891*EXP(-40.26*AF9) -> 0.64565443 | AI9: =AG9-AH9 -> 0.012345567
A10: ='DNC4 FF'!A10 -> 7 | B10: ='DNC4 FF'!B10 -> 13 | C10: ='DNC4 FF'!C10 -> 16 | D10: ='DNC4 FF'!D10 -> 7 | E10: ='DNC4 FF'!E10 -> 7 | F10: ='DNC4 FF'!F10 -> 8 | G10: ='DNC4 FF'!G10 -> 3 | H10: ='DNC4 FF'!H10 -> 4 | ... L10: ='DNC4 FF'!L10 -> 7.2 | N10: ='# Out FF'!A10 -> 7 | O10: ='# Out FF'!B10 -> 658 | P10: ='# Out FF'!C10 -> 842 | Q10: ='# Out FF'!D10 -> 713 | R10: ='# Out FF'!E10 -> 687 | S10: ='# Out FF'!F10 -> 748 | T10: ='# Out FF'!G10 -> 794 | U10: ='# Out FF'!H10 -> 550 | ... Y10: ='# Out FF'!L10 -> 678.6 | AB10: 13 | AC10: 453 | AF10: =AB10/1000 -> 0.013 | AG10: =AC10/1000 -> 0.453 | AH10: =0.891*EXP(-40.26*AF10) -> 0.52793038 | AI10: =AG10-AH10 -> -0.074930384
A11: ='DNC4 FF'!A11 -> 8 | B11: ='DNC4 FF'!B11 -> 15 | C11: ='DNC4 FF'!C11 -> 15 | D11: ='DNC4 FF'!D11 -> 7 | E11: ='DNC4 FF'!E11 -> 19 | F11: ='DNC4 FF'!F11 -> 10 | G11: ='DNC4 FF'!G11 -> 8 | H11: ='DNC4 FF'!H11 -> 2 | ... L11: ='DNC4 FF'!L11 -> 9.5 | N11: ='# Out FF'!A11 -> 8 | O11: ='# Out FF'!B11 -> 453 | P11: ='# Out FF'!C11 -> 458 | Q11: ='# Out FF'!D11 -> 759 | R11: ='# Out FF'!E11 -> 745 | S11: ='# Out FF'!F11 -> 685 | T11: ='# Out FF'!G11 -> 782 | U11: ='# Out FF'!H11 -> 767 | ... Y11: ='# Out FF'!L11 -> 668.4 | AB11: 15 | AC11: 346 | AF11: =AB11/1000 -> 0.015 | AG11: =AC11/1000 -> 0.346 | AH11: =0.891*EXP(-40.26*AF11) -> 0.48708782 | AI11: =AG11-AH11 -> -0.14108782
A12: ='DNC4 FF'!A12 -> 9 | B12: ='DNC4 FF'!B12 -> 20 | C12: ='DNC4 FF'!C12 -> 18 | D12: ='DNC4 FF'!D12 -> 6 | E12: ='DNC4 FF'!E12 -> 15 | F12: ='DNC4 FF'!F12 -> 10 | G12: ='DNC4 FF'!G12 -> 4 | H12: ='DNC4 FF'!H12 -> 5 | ... L12: ='DNC4 FF'!L12 -> 9.9 | N12: ='# Out FF'!A12 -> 9 | O12: ='# Out FF'!B12 -> 346 | P12: ='# Out FF'!C12 -> 382 | Q12: ='# Out FF'!D12 -> 755 | R12: ='# Out FF'!E12 -> 484 | S12: ='# Out FF'!F12 -> 841 | T12: ='# Out FF'!G12 -> 702 | U12: ='# Out FF'!H12 -> 766 | ... Y12: ='# Out FF'!L12 -> 631.7 | AB12: 20 | AC12: 511 | AF12: =AB12/1000 -> 0.02 | AG12: =AC12/1000 -> 0.511 | AH12: =0.891*EXP(-40.26*AF12) -> 0.39827568 | AI12: =AG12-AH12 -> 0.11272432
A13: ='DNC4 FF'!A13 -> 10 | B13: ='DNC4 FF'!B13 -> 16 | C13: ='DNC4 FF'!C13 -> 26 | D13: ='DNC4 FF'!D13 -> 12 | E13: ='DNC4 FF'!E13 -> 15 | F13: ='DNC4 FF'!F13 -> 9 | G13: ='DNC4 FF'!G13 -> 10 | H13: ='DNC4 FF'!H13 -> 2 | ... L13: ='DNC4 FF'!L13 -> 10.9 | N13: ='# Out FF'!A13 -> 10 | O13: ='# Out FF'!B13 -> 511 | P13: ='# Out FF'!C13 -> 530 | Q13: ='# Out FF'!D13 -> 722 | R13: ='# Out FF'!E13 -> 345 | S13: ='# Out FF'!F13 -> 847 | T13: ='# Out FF'!G13 -> 787 | U13: ='# Out FF'!H13 -> 551 | ... Y13: ='# Out FF'!L13 -> 630.3 | AB13: 16 | AC13: 447 | AF13: =AB13/1000 -> 0.016 | AG13: =AC13/1000 -> 0.447 | AH13: =0.891*EXP(-40.26*AF13) -> 0.46786717 | AI13: =AG13-AH13 -> -0.020867168
A14: ='DNC4 FF'!A14 -> 11 | B14: ='DNC4 FF'!B14 -> 13 | C14: ='DNC4 FF'!C14 -> 7 | D14: ='DNC4 FF'!D14 -> 11 | E14: ='DNC4 FF'!E14 -> 20 | F14: ='DNC4 FF'!F14 -> 15 | G14: ='DNC4 FF'!G14 -> 12 | H14: ='DNC4 FF'!H14 -> 7 | ... L14: ='DNC4 FF'!L14 -> 9.9 | N14: ='# Out FF'!A14 -> 11 | O14: ='# Out FF'!B14 -> 447 | P14: ='# Out FF'!C14 -> 284 | Q14: ='# Out FF'!D14 -> 536 | R14: ='# Out FF'!E14 -> 335 | S14: ='# Out FF'!F14 -> 686 | T14: ='# Out FF'!G14 -> 829 | U14: ='# Out FF'!H14 -> 759 | ... Y14: ='# Out FF'!L14 -> 587.8 | AB14: 13 | AC14: 439 | AF14: =AB14/1000 -> 0.013 | AG14: =AC14/1000 -> 0.439 | AH14: =0.891*EXP(-40.26*AF14) -> 0.52793038 | AI14: =AG14-AH14 -> -0.088930384
A15: ='DNC4 FF'!A15 -> 12 | B15: ='DNC4 FF'!B15 -> 5 | C15: ='DNC4 FF'!C15 -> 4 | D15: ='DNC4 FF'!D15 -> 18 | E15: ='DNC4 FF'!E15 -> 14 | F15: ='DNC4 FF'!F15 -> 17 | G15: ='DNC4 FF'!G15 -> 14 | H15: ='DNC4 FF'!H15 -> 6 | ... L15: ='DNC4 FF'!L15 -> 9.2 | N15: ='# Out FF'!A15 -> 12 | O15: ='# Out FF'!B15 -> 439 | P15: ='# Out FF'!C15 -> 741 | Q15: ='# Out FF'!D15 -> 652 | R15: ='# Out FF'!E15 -> 504 | S15: ='# Out FF'!F15 -> 366 | T15: ='# Out FF'!G15 -> 580 | U15: ='# Out FF'!H15 -> 763 | ... Y15: ='# Out FF'!L15 -> 634.8 | AB15: 5 | AC15: 535 | AF15: =AB15/1000 -> 0.005 | AG15: =AC15/1000 -> 0.535 | AH15: =0.891*EXP(-40.26*AF15) -> 0.72854138 | AI15: =AG15-AH15 -> -0.19354138
... A78: ='DNC4 FF'!A78 -> 75 | B78: ='DNC4 FF'!B78 -> 0 | C78: ='DNC4 FF'!C78 -> 0 | D78: ='DNC4 FF'!D78 -> #REF! | E78: ='DNC4 FF'!E78 -> 0 | F78: ='DNC4 FF'!F78 -> 0 | G78: ='DNC4 FF'!G78 -> 1 | H78: ='DNC4 FF'!H78 -> 8 | ... L78: ='DNC4 FF'!L78 -> #REF! | N78: ='# Out FF'!A78 -> 75 | O78: ='# Out FF'!B78 -> 999 | P78: ='# Out FF'!C78 -> 996 | Q78: ='# Out FF'!D78 -> 1000 | R78: ='# Out FF'!E78 -> 996 | S78: ='# Out FF'!F78 -> 790 | T78: ='# Out FF'!G78 -> 810 | U78: ='# Out FF'!H78 -> 774 | ... Y78: ='# Out FF'!L78 -> 893.6 | AB78: 0 | AC78: 999 | AF78: =AB78/1000 -> 0 | AG78: =AC78/1000 -> 0.999 | AH78: =0.891*EXP(-40.26*AF78) -> 0.891 | AI78: =AG78-AH78 -> 0.108
A79: ='DNC4 FF'!A79 -> 76 | B79: ='DNC4 FF'!B79 -> 0 | C79: ='DNC4 FF'!C79 -> #REF! | D79: ='DNC4 FF'!D79 -> #REF! | E79: ='DNC4 FF'!E79 -> 0 | F79: ='DNC4 FF'!F79 -> 2 | G79: ='DNC4 FF'!G79 -> 4 | H79: ='DNC4 FF'!H79 -> 0 | ... L79: ='DNC4 FF'!L79 -> #REF! | N79: ='# Out FF'!A79 -> 76 | O79: ='# Out FF'!B79 -> 999 | P79: ='# Out FF'!C79 -> 1000 | Q79: ='# Out FF'!D79 -> 1000 | R79: ='# Out FF'!E79 -> 998 | S79: ='# Out FF'!F79 -> 995 | T79: ='# Out FF'!G79 -> 791 | U79: ='# Out FF'!H79 -> 697 | ... Y79: ='# Out FF'!L79 -> 905.6 | AB79: {=C3:C77} -> 0 | AC79: {=P4:P78} -> 996 | AF79: =AB79/1000 -> 0 | AG79: =AC79/1000 -> 0.996 | AH79: =0.891*EXP(-40.26*AF79) -> 0.891 | AI79: =AG79-AH79 -> 0.105
A80: ='DNC4 FF'!A80 -> 77 | B80: ='DNC4 FF'!B80 -> #REF! | C80: ='DNC4 FF'!C80 -> #REF! | D80: ='DNC4 FF'!D80 -> #REF! | E80: ='DNC4 FF'!E80 -> #REF! | F80: ='DNC4 FF'!F80 -> 4 | G80: ='DNC4 FF'!G80 -> 2 | H80: ='DNC4 FF'!H80 -> 2 | ... L80: ='DNC4 FF'!L80 -> #REF! | N80: ='# Out FF'!A80 -> 77 | O80: ='# Out FF'!B80 -> 1000 | P80: ='# Out FF'!C80 -> 1000 | Q80: ='# Out FF'!D80 -> 1000 | R80: ='# Out FF'!E80 -> 1000 | S80: ='# Out FF'!F80 -> 787 | T80: ='# Out FF'!G80 -> 803 | U80: ='# Out FF'!H80 -> 986 | ... Y80: ='# Out FF'!L80 -> 935.6 | AB80: 0 | AC80: 996 | AF80: =AB80/1000 -> 0 | AG80: =AC80/1000 -> 0.996 | AH80: =0.891*EXP(-40.26*AF80) -> 0.891 | AI80: =AG80-AH80 -> 0.105
A81: ='DNC4 FF'!A81 -> 78 | B81: ='DNC4 FF'!B81 -> #REF! | C81: ='DNC4 FF'!C81 -> #REF! | D81: ='DNC4 FF'!D81 -> #REF! | E81: ='DNC4 FF'!E81 -> #REF! | F81: ='DNC4 FF'!F81 -> 2 | G81: ='DNC4 FF'!G81 -> 2 | H81: ='DNC4 FF'!H81 -> 1 | ... L81: ='DNC4 FF'!L81 -> #REF! | N81: ='# Out FF'!A81 -> 78 | O81: ='# Out FF'!B81 -> 1000 | P81: ='# Out FF'!C81 -> 1000 | Q81: ='# Out FF'!D81 -> 1000 | R81: ='# Out FF'!E81 -> 1000 | S81: ='# Out FF'!F81 -> 786 | T81: ='# Out FF'!G81 -> 790 | U81: ='# Out FF'!H81 -> 769 | ... Y81: ='# Out FF'!L81 -> 890.1 | AB81: 0 | AC81: 998 | AF81: =AB81/1000 -> 0 | AG81: =AC81/1000 -> 0.998 | AH81: =0.891*EXP(-40.26*AF81) -> 0.891 | AI81: =AG81-AH81 -> 0.107
A82: ='DNC4 FF'!A82 -> 79 | B82: ='DNC4 FF'!B82 -> #REF! | C82: ='DNC4 FF'!C82 -> #REF! | D82: ='DNC4 FF'!D82 -> #REF! | E82: ='DNC4 FF'!E82 -> #REF! | F82: ='DNC4 FF'!F82 -> 4 | G82: ='DNC4 FF'!G82 -> 1 | H82: ='DNC4 FF'!H82 -> 0 | ... L82: ='DNC4 FF'!L82 -> #REF! | N82: ='# Out FF'!A82 -> 79 | O82: ='# Out FF'!B82 -> 1000 | P82: ='# Out FF'!C82 -> 1000 | Q82: ='# Out FF'!D82 -> 1000 | R82: ='# Out FF'!E82 -> 1000 | S82: ='# Out FF'!F82 -> 783 | T82: ='# Out FF'!G82 -> 796 | U82: ='# Out FF'!H82 -> 819 | ... Y82: ='# Out FF'!L82 -> 889.6 | AB82: 2 | AC82: 796 | AF82: =AB82/1000 -> 0.002 | AG82: =AC82/1000 -> 0.796 | AH82: =0.891*EXP(-40.26*AF82) -> 0.82206908 | AI82: =AG82-AH82 -> -0.026069078
A83: ='DNC4 FF'!A83 -> 80 | B83: ='DNC4 FF'!B83 -> #REF! | C83: ='DNC4 FF'!C83 -> #REF! | D83: ='DNC4 FF'!D83 -> #REF! | E83: ='DNC4 FF'!E83 -> #REF! | F83: ='DNC4 FF'!F83 -> 3 | G83: ='DNC4 FF'!G83 -> 3 | H83: ='DNC4 FF'!H83 -> 1 | ... L83: ='DNC4 FF'!L83 -> #REF! | N83: ='# Out FF'!A83 -> 80 | O83: ='# Out FF'!B83 -> 1000 | P83: ='# Out FF'!C83 -> 1000 | Q83: ='# Out FF'!D83 -> 1000 | R83: ='# Out FF'!E83 -> 1000 | S83: ='# Out FF'!F83 -> 785 | T83: ='# Out FF'!G83 -> 786 | U83: ='# Out FF'!H83 -> 995 | ... Y83: ='# Out FF'!L83 -> 891.7 | AB83: 1 | AC83: 807 | AF83: =AB83/1000 -> 0.001 | AG83: =AC83/1000 -> 0.807 | AH83: =0.891*EXP(-40.26*AF83) -> 0.85584084 | AI83: =AG83-AH83 -> -0.048840843
A84: ='DNC4 FF'!A84 -> 81 | B84: ='DNC4 FF'!B84 -> #REF! | C84: ='DNC4 FF'!C84 -> #REF! | D84: ='DNC4 FF'!D84 -> #REF! | E84: ='DNC4 FF'!E84 -> #REF! | F84: ='DNC4 FF'!F84 -> 1 | G84: ='DNC4 FF'!G84 -> 3 | H84: ='DNC4 FF'!H84 -> 0 | ... L84: ='DNC4 FF'!L84 -> #REF! | N84: ='# Out FF'!A84 -> 81 | O84: ='# Out FF'!B84 -> 1000 | P84: ='# Out FF'!C84 -> 1000 | Q84: ='# Out FF'!D84 -> 1000 | R84: ='# Out FF'!E84 -> 1000 | S84: ='# Out FF'!F84 -> 761 | T84: ='# Out FF'!G84 -> 789 | U84: ='# Out FF'!H84 -> 808 | ... Y84: ='# Out FF'!L84 -> 860.3 | AB84: 4 | AC84: 795 | AF84: =AB84/1000 -> 0.004 | AG84: =AC84/1000 -> 0.795 | AH84: =0.891*EXP(-40.26*AF84) -> 0.7584709 | AI84: =AG84-AH84 -> 0.036529104
A85: ='DNC4 FF'!A85 -> 82 | B85: ='DNC4 FF'!B85 -> #REF! | C85: ='DNC4 FF'!C85 -> #REF! | D85: ='DNC4 FF'!D85 -> #REF! | E85: ='DNC4 FF'!E85 -> #REF! | F85: ='DNC4 FF'!F85 -> 2 | G85: ='DNC4 FF'!G85 -> 1 | H85: ='DNC4 FF'!H85 -> 0 | ... L85: ='DNC4 FF'!L85 -> #REF! | N85: ='# Out FF'!A85 -> 82 | O85: ='# Out FF'!B85 -> 1000 | P85: ='# Out FF'!C85 -> 1000 | Q85: ='# Out FF'!D85 -> 1000 | R85: ='# Out FF'!E85 -> 1000 | S85: ='# Out FF'!F85 -> 796 | T85: ='# Out FF'!G85 -> 786 | U85: ='# Out FF'!H85 -> 996 | ... Y85: ='# Out FF'!L85 -> 910.4 | AB85: 10 | AC85: 842 | AF85: =AB85/1000 -> 0.01 | AG85: =AC85/1000 -> 0.842 | AH85: =0.891*EXP(-40.26*AF85) -> 0.59570431 | AI85: =AG85-AH85 -> 0.24629569
A86: ='DNC4 FF'!A86 -> 83 | B86: ='DNC4 FF'!B86 -> #REF! | C86: ='DNC4 FF'!C86 -> #REF! | D86: ='DNC4 FF'!D86 -> #REF! | E86: ='DNC4 FF'!E86 -> #REF! | F86: ='DNC4 FF'!F86 -> 0 | G86: ='DNC4 FF'!G86 -> 2 | H86: ='DNC4 FF'!H86 -> 2 | ... L86: ='DNC4 FF'!L86 -> #REF! | N86: ='# Out FF'!A86 -> 83 | O86: ='# Out FF'!B86 -> 1000 | P86: ='# Out FF'!C86 -> 1000 | Q86: ='# Out FF'!D86 -> 1000 | R86: ='# Out FF'!E86 -> 1000 | S86: ='# Out FF'!F86 -> 788 | T86: ='# Out FF'!G86 -> 787 | U86: ='# Out FF'!H86 -> 997 | ... Y86: ='# Out FF'!L86 -> 913.5 | AB86: 16 | AC86: 458 | AF86: =AB86/1000 -> 0.016 | AG86: =AC86/1000 -> 0.458 | AH86: =0.891*EXP(-40.26*AF86) -> 0.46786717 | AI86: =AG86-AH86 -> -0.0098671684
A87: ='DNC4 FF'!A87 -> 84 | B87: ='DNC4 FF'!B87 -> #REF! | C87: ='DNC4 FF'!C87 -> #REF! | D87: ='DNC4 FF'!D87 -> #REF! | E87: ='DNC4 FF'!E87 -> #REF! | F87: ='DNC4 FF'!F87 -> 0 | G87: ='DNC4 FF'!G87 -> 0 | H87: ='DNC4 FF'!H87 -> 1 | ... L87: ='DNC4 FF'!L87 -> #REF! | N87: ='# Out FF'!A87 -> 84 | O87: ='# Out FF'!B87 -> 1000 | P87: ='# Out FF'!C87 -> 1000 | Q87: ='# Out FF'!D87 -> 1000 | R87: ='# Out FF'!E87 -> 1000 | S87: ='# Out FF'!F87 -> 996 | T87: ='# Out FF'!G87 -> 797 | U87: ='# Out FF'!H87 -> 782 | ... Y87: ='# Out FF'!L87 -> 893.4 | AB87: 15 | AC87: 382 | AF87: =AB87/1000 -> 0.015 | AG87: =AC87/1000 -> 0.382 | AH87: =0.891*EXP(-40.26*AF87) -> 0.48708782 | AI87: =AG87-AH87 -> -0.10508782
A88: ='DNC4 FF'!A88 -> 85 | B88: ='DNC4 FF'!B88 -> #REF! | C88: ='DNC4 FF'!C88 -> #REF! | D88: ='DNC4 FF'!D88 -> #REF! | E88: ='DNC4 FF'!E88 -> #REF! | F88: ='DNC4 FF'!F88 -> 0 | G88: ='DNC4 FF'!G88 -> 0 | H88: ='DNC4 FF'!H88 -> 0 | ... L88: ='DNC4 FF'!L88 -> #REF! | N88: ='# Out FF'!A88 -> 85 | O88: ='# Out FF'!B88 -> 1000 | P88: ='# Out FF'!C88 -> 1000 | Q88: ='# Out FF'!D88 -> 1000 | R88: ='# Out FF'!E88 -> 1000 | S88: ='# Out FF'!F88 -> 995 | T88: ='# Out FF'!G88 -> 996 | U88: ='# Out FF'!H88 -> 812 | ... Y88: ='# Out FF'!L88 -> 938.8 | AB88: 18 | AC88: 530 | AF88: =AB88/1000 -> 0.018 | AG88: =AC88/1000 -> 0.53 | AH88: =0.891*EXP(-40.26*AF88) -> 0.4316713 | AI88: =AG88-AH88 -> 0.098328696
A89: ='DNC4 FF'!A89 -> 86 | B89: ='DNC4 FF'!B89 -> #REF! | C89: ='DNC4 FF'!C89 -> #REF! | D89: ='DNC4 FF'!D89 -> #REF! | E89: ='DNC4 FF'!E89 -> #REF! | F89: ='DNC4 FF'!F89 -> #REF! | G89: ='DNC4 FF'!G89 -> 0 | H89: ='DNC4 FF'!H89 -> 1 | ... L89: ='DNC4 FF'!L89 -> #REF! | N89: ='# Out FF'!A89 -> 86 | O89: ='# Out FF'!B89 -> 1000 | P89: ='# Out FF'!C89 -> 1000 | Q89: ='# Out FF'!D89 -> 1000 | R89: ='# Out FF'!E89 -> 1000 | S89: ='# Out FF'!F89 -> 1000 | T89: ='# Out FF'!G89 -> 996 | U89: ='# Out FF'!H89 -> 996 | ... Y89: ='# Out FF'!L89 -> 935.2 | AB89: 26 | AC89: 284 | AF89: =AB89/1000 -> 0.026 | AG89: =AC89/1000 -> 0.284 | AH89: =0.891*EXP(-40.26*AF89) -> 0.31280639 | AI89: =AG89-AH89 -> -0.028806387
A90: ='DNC4 FF'!A90 -> 87 | B90: ='DNC4 FF'!B90 -> #REF! | C90: ='DNC4 FF'!C90 -> #REF! | D90: ='DNC4 FF'!D90 -> #REF! | E90: ='DNC4 FF'!E90 -> #REF! | F90: ='DNC4 FF'!F90 -> #REF! | G90: ='DNC4 FF'!G90 -> 1 | H90: ='DNC4 FF'!H90 -> 0 | ... L90: ='DNC4 FF'!L90 -> #REF! | N90: ='# Out FF'!A90 -> 87 | O90: ='# Out FF'!B90 -> 1000 | P90: ='# Out FF'!C90 -> 1000 | Q90: ='# Out FF'!D90 -> 1000 | R90: ='# Out FF'!E90 -> 1000 | S90: ='# Out FF'!F90 -> 1000 | T90: ='# Out FF'!G90 -> 996 | U90: ='# Out FF'!H90 -> 998 | ... Y90: ='# Out FF'!L90 -> 954.8 | AB90: 7 | AC90: 741 | AF90: =AB90/1000 -> 0.007 | AG90: =AC90/1000 -> 0.741 | AH90: =0.891*EXP(-40.26*AF90) -> 0.67217883 | AI90: =AG90-AH90 -> 0.068821166
A91: ='DNC4 FF'!A91 -> 88 | B91: ='DNC4 FF'!B91 -> #REF! | C91: ='DNC4 FF'!C91 -> #REF! | D91: ='DNC4 FF'!D91 -> #REF! | E91: ='DNC4 FF'!E91 -> #REF! | F91: ='DNC4 FF'!F91 -> #REF! | G91: ='DNC4 FF'!G91 -> 1 | H91: ='DNC4 FF'!H91 -> 0 | ... L91: ='DNC4 FF'!L91 -> #REF! | N91: ='# Out FF'!A91 -> 88 | O91: ='# Out FF'!B91 -> 1000 | P91: ='# Out FF'!C91 -> 1000 | Q91: ='# Out FF'!D91 -> 1000 | R91: ='# Out FF'!E91 -> 1000 | S91: ='# Out FF'!F91 -> 1000 | T91: ='# Out FF'!G91 -> 800 | U91: ='# Out FF'!H91 -> 999 | ... Y91: ='# Out FF'!L91 -> 918 | AB91: 4 | AC91: 776 | AF91: =AB91/1000 -> 0.004 | AG91: =AC91/1000 -> 0.776 | AH91: =0.891*EXP(-40.26*AF91) -> 0.7584709 | AI91: =AG91-AH91 -> 0.017529104
... A153: ='DNC4 FF'!A153 -> 150 | B153: ='DNC4 FF'!B153 -> #REF! | C153: ='DNC4 FF'!C153 -> #REF! | D153: ='DNC4 FF'!D153 -> #REF! | E153: ='DNC4 FF'!E153 -> #REF! | F153: ='DNC4 FF'!F153 -> #REF! | G153: ='DNC4 FF'!G153 -> #REF! | H153: ='DNC4 FF'!H153 -> #REF! | ... L153: ='DNC4 FF'!L153 -> #REF! | N153: ='# Out FF'!A153 -> 150 | O153: ='# Out FF'!B153 -> 1000 | P153: ='# Out FF'!C153 -> 1000 | Q153: ='# Out FF'!D153 -> 1000 | R153: ='# Out FF'!E153 -> 1000 | S153: ='# Out FF'!F153 -> 1000 | T153: ='# Out FF'!G153 -> 1000 | U153: ='# Out FF'!H153 -> 1000 | ... Y153: ='# Out FF'!L153 -> 956.5 | AB153: 0 | AC153: 996 | AF153: =AB153/1000 -> 0 | AG153: =AC153/1000 -> 0.996 | AH153: =0.891*EXP(-40.26*AF153) -> 0.891 | AI153: =AG153-AH153 -> 0.105
A154: ='DNC4 FF'!A154 -> 151 | B154: ='DNC4 FF'!B154 -> #REF! | C154: ='DNC4 FF'!C154 -> #REF! | D154: ='DNC4 FF'!D154 -> #REF! | E154: ='DNC4 FF'!E154 -> #REF! | F154: ='DNC4 FF'!F154 -> #REF! | G154: ='DNC4 FF'!G154 -> #REF! | H154: ='DNC4 FF'!H154 -> #REF! | ... L154: ='DNC4 FF'!L154 -> #REF! | N154: ='# Out FF'!A154 -> 151 | O154: ='# Out FF'!B154 -> 1000 | P154: ='# Out FF'!C154 -> 1000 | Q154: ='# Out FF'!D154 -> 1000 | R154: ='# Out FF'!E154 -> 1000 | S154: ='# Out FF'!F154 -> 1000 | T154: ='# Out FF'!G154 -> 1000 | U154: ='# Out FF'!H154 -> 1000 | ... Y154: ='# Out FF'!L154 -> 976.2 | AB154: {=D3:D55} -> 0 | AC154: {=Q4:Q56} -> 995 | AF154: =AB154/1000 -> 0 | AG154: =AC154/1000 -> 0.995 | AH154: =0.891*EXP(-40.26*AF154) -> 0.891 | AI154: =AG154-AH154 -> 0.104
A155: ='DNC4 FF'!A155 -> 152 | B155: ='DNC4 FF'!B155 -> #REF! | C155: ='DNC4 FF'!C155 -> #REF! | D155: ='DNC4 FF'!D155 -> #REF! | E155: ='DNC4 FF'!E155 -> #REF! | F155: ='DNC4 FF'!F155 -> #REF! | G155: ='DNC4 FF'!G155 -> #REF! | H155: ='DNC4 FF'!H155 -> #REF! | ... L155: ='DNC4 FF'!L155 -> #REF! | N155: ='# Out FF'!A155 -> 152 | O155: ='# Out FF'!B155 -> 1000 | P155: ='# Out FF'!C155 -> 1000 | Q155: ='# Out FF'!D155 -> 1000 | R155: ='# Out FF'!E155 -> 1000 | S155: ='# Out FF'!F155 -> 1000 | T155: ='# Out FF'!G155 -> 1000 | U155: ='# Out FF'!H155 -> 1000 | ... Y155: ='# Out FF'!L155 -> 980.6 | AB155: 0 | AC155: 994 | AF155: =AB155/1000 -> 0 | AG155: =AC155/1000 -> 0.994 | AH155: =0.891*EXP(-40.26*AF155) -> 0.891 | AI155: =AG155-AH155 -> 0.103
A156: ='DNC4 FF'!A156 -> 153 | B156: ='DNC4 FF'!B156 -> #REF! | C156: ='DNC4 FF'!C156 -> #REF! | D156: ='DNC4 FF'!D156 -> #REF! | E156: ='DNC4 FF'!E156 -> #REF! | F156: ='DNC4 FF'!F156 -> #REF! | G156: ='DNC4 FF'!G156 -> #REF! | H156: ='DNC4 FF'!H156 -> #REF! | ... L156: ='DNC4 FF'!L156 -> #REF! | N156: ='# Out FF'!A156 -> 153 | O156: ='# Out FF'!B156 -> 1000 | P156: ='# Out FF'!C156 -> 1000 | Q156: ='# Out FF'!D156 -> 1000 | R156: ='# Out FF'!E156 -> 1000 | S156: ='# Out FF'!F156 -> 1000 | T156: ='# Out FF'!G156 -> 1000 | U156: ='# Out FF'!H156 -> 1000 | ... Y156: ='# Out FF'!L156 -> 998.9 | AB156: 0 | AC156: 994 | AF156: =AB156/1000 -> 0 | AG156: =AC156/1000 -> 0.994 | AH156: =0.891*EXP(-40.26*AF156) -> 0.891 | AI156: =AG156-AH156 -> 0.103
A157: ='DNC4 FF'!A157 -> 154 | B157: ='DNC4 FF'!B157 -> #REF! | C157: ='DNC4 FF'!C157 -> #REF! | D157: ='DNC4 FF'!D157 -> #REF! | E157: ='DNC4 FF'!E157 -> #REF! | F157: ='DNC4 FF'!F157 -> #REF! | G157: ='DNC4 FF'!G157 -> #REF! | H157: ='DNC4 FF'!H157 -> #REF! | ... L157: ='DNC4 FF'!L157 -> #REF! | N157: ='# Out FF'!A157 -> 154 | O157: ='# Out FF'!B157 -> 1000 | P157: ='# Out FF'!C157 -> 1000 | Q157: ='# Out FF'!D157 -> 1000 | R157: ='# Out FF'!E157 -> 1000 | S157: ='# Out FF'!F157 -> 1000 | T157: ='# Out FF'!G157 -> 1000 | U157: ='# Out FF'!H157 -> 1000 | ... Y157: ='# Out FF'!L157 -> 980.1 | AB157: 2 | AC157: 775 | AF157: =AB157/1000 -> 0.002 | AG157: =AC157/1000 -> 0.775 | AH157: =0.891*EXP(-40.26*AF157) -> 0.82206908 | AI157: =AG157-AH157 -> -0.047069078
A158: ='DNC4 FF'!A158 -> 155 | B158: ='DNC4 FF'!B158 -> #REF! | C158: ='DNC4 FF'!C158 -> #REF! | D158: ='DNC4 FF'!D158 -> #REF! | E158: ='DNC4 FF'!E158 -> #REF! | F158: ='DNC4 FF'!F158 -> #REF! | G158: ='DNC4 FF'!G158 -> #REF! | H158: ='DNC4 FF'!H158 -> #REF! | ... L158: ='DNC4 FF'!L158 -> #REF! | N158: ='# Out FF'!A158 -> 155 | O158: ='# Out FF'!B158 -> 1000 | P158: ='# Out FF'!C158 -> 1000 | Q158: ='# Out FF'!D158 -> 1000 | R158: ='# Out FF'!E158 -> 1000 | S158: ='# Out FF'!F158 -> 1000 | T158: ='# Out FF'!G158 -> 1000 | U158: ='# Out FF'!H158 -> 1000 | ... Y158: ='# Out FF'!L158 -> 999.5 | AB158: 4 | AC158: 786 | AF158: =AB158/1000 -> 0.004 | AG158: =AC158/1000 -> 0.786 | AH158: =0.891*EXP(-40.26*AF158) -> 0.7584709 | AI158: =AG158-AH158 -> 0.027529104
A159: ='DNC4 FF'!A159 -> 156 | B159: ='DNC4 FF'!B159 -> #REF! | C159: ='DNC4 FF'!C159 -> #REF! | D159: ='DNC4 FF'!D159 -> #REF! | E159: ='DNC4 FF'!E159 -> #REF! | F159: ='DNC4 FF'!F159 -> #REF! | G159: ='DNC4 FF'!G159 -> #REF! | H159: ='DNC4 FF'!H159 -> #REF! | ... L159: ='DNC4 FF'!L159 -> #REF! | N159: ='# Out FF'!A159 -> 156 | O159: ='# Out FF'!B159 -> 1000 | P159: ='# Out FF'!C159 -> 1000 | Q159: ='# Out FF'!D159 -> 1000 | R159: ='# Out FF'!E159 -> 1000 | S159: ='# Out FF'!F159 -> 1000 | T159: ='# Out FF'!G159 -> 1000 | U159: ='# Out FF'!H159 -> 1000 | ... Y159: ='# Out FF'!L159 -> 978.5 | AB159: 5 | AC159: 532 | AF159: =AB159/1000 -> 0.005 | AG159: =AC159/1000 -> 0.532 | AH159: =0.891*EXP(-40.26*AF159) -> 0.72854138 | AI159: =AG159-AH159 -> -0.19654138
A160: ='DNC4 FF'!A160 -> 157 | B160: ='DNC4 FF'!B160 -> #REF! | C160: ='DNC4 FF'!C160 -> #REF! | D160: ='DNC4 FF'!D160 -> #REF! | E160: ='DNC4 FF'!E160 -> #REF! | F160: ='DNC4 FF'!F160 -> #REF! | G160: ='DNC4 FF'!G160 -> #REF! | H160: ='DNC4 FF'!H160 -> #REF! | ... L160: ='DNC4 FF'!L160 -> #REF! | N160: ='# Out FF'!A160 -> 157 | O160: ='# Out FF'!B160 -> 1000 | P160: ='# Out FF'!C160 -> 1000 | Q160: ='# Out FF'!D160 -> 1000 | R160: ='# Out FF'!E160 -> 1000 | S160: ='# Out FF'!F160 -> 1000 | T160: ='# Out FF'!G160 -> 1000 | U160: ='# Out FF'!H160 -> 1000 | ... Y160: ='# Out FF'!L160 -> 978.4 | AB160: 9 | AC160: 713 | AF160: =AB160/1000 -> 0.009 | AG160: =AC160/1000 -> 0.713 | AH160: =0.891*EXP(-40.26*AF160) -> 0.62017669 | AI160: =AG160-AH160 -> 0.092823306
A161: ='DNC4 FF'!A161 -> 158 | B161: ='DNC4 FF'!B161 -> #REF! | C161: ='DNC4 FF'!C161 -> #REF! | D161: ='DNC4 FF'!D161 -> #REF! | E161: ='DNC4 FF'!E161 -> #REF! | F161: ='DNC4 FF'!F161 -> #REF! | G161: ='DNC4 FF'!G161 -> #REF! | H161: ='DNC4 FF'!H161 -> #REF! | ... L161: ='DNC4 FF'!L161 -> #REF! | N161: ='# Out FF'!A161 -> 158 | O161: ='# Out FF'!B161 -> 1000 | P161: ='# Out FF'!C161 -> 1000 | Q161: ='# Out FF'!D161 -> 1000 | R161: ='# Out FF'!E161 -> 1000 | S161: ='# Out FF'!F161 -> 1000 | T161: ='# Out FF'!G161 -> 1000 | U161: ='# Out FF'!H161 -> 1000 | ... Y161: ='# Out FF'!L161 -> 979.1 | AB161: 7 | AC161: 759 | AF161: =AB161/1000 -> 0.007 | AG161: =AC161/1000 -> 0.759 | AH161: =0.891*EXP(-40.26*AF161) -> 0.67217883 | AI161: =AG161-AH161 -> 0.086821166
A162: ='DNC4 FF'!A162 -> 159 | B162: ='DNC4 FF'!B162 -> #REF! | C162: ='DNC4 FF'!C162 -> #REF! | D162: ='DNC4 FF'!D162 -> #REF! | E162: ='DNC4 FF'!E162 -> #REF! | F162: ='DNC4 FF'!F162 -> #REF! | G162: ='DNC4 FF'!G162 -> #REF! | H162: ='DNC4 FF'!H162 -> #REF! | ... L162: ='DNC4 FF'!L162 -> #REF! | N162: ='# Out FF'!A162 -> 159 | O162: ='# Out FF'!B162 -> 1000 | P162: ='# Out FF'!C162 -> 1000 | Q162: ='# Out FF'!D162 -> 1000 | R162: ='# Out FF'!E162 -> 1000 | S162: ='# Out FF'!F162 -> 1000 | T162: ='# Out FF'!G162 -> 1000 | U162: ='# Out FF'!H162 -> 1000 | ... Y162: ='# Out FF'!L162 -> 999.5 | AB162: 7 | AC162: 755 | AF162: =AB162/1000 -> 0.007 | AG162: =AC162/1000 -> 0.755 | AH162: =0.891*EXP(-40.26*AF162) -> 0.67217883 | AI162: =AG162-AH162 -> 0.082821166
A163: ='DNC4 FF'!A163 -> 160 | B163: ='DNC4 FF'!B163 -> #REF! | C163: ='DNC4 FF'!C163 -> #REF! | D163: ='DNC4 FF'!D163 -> #REF! | E163: ='DNC4 FF'!E163 -> #REF! | F163: ='DNC4 FF'!F163 -> #REF! | G163: ='DNC4 FF'!G163 -> #REF! | H163: ='DNC4 FF'!H163 -> #REF! | ... L163: ='DNC4 FF'!L163 -> #REF! | N163: ='# Out FF'!A163 -> 160 | O163: ='# Out FF'!B163 -> 1000 | P163: ='# Out FF'!C163 -> 1000 | Q163: ='# Out FF'!D163 -> 1000 | R163: ='# Out FF'!E163 -> 1000 | S163: ='# Out FF'!F163 -> 1000 | T163: ='# Out FF'!G163 -> 1000 | U163: ='# Out FF'!H163 -> 1000 | ... Y163: ='# Out FF'!L163 -> 999.6 | AB163: 6 | AC163: 722 | AF163: =AB163/1000 -> 0.006 | AG163: =AC163/1000 -> 0.722 | AH163: =0.891*EXP(-40.26*AF163) -> 0.6997929 | AI163: =AG163-AH163 -> 0.022207105
...

Sheet Infected NF
A1: Number of Infections per timestep
A2: Time Step | B2: Run 1 | C2: Run 2 | D2: Run 3 | E2: Run 4 | F2: Run 5 | G2: Run 6 | H2: Run 7 | I2: Run 8 | J2: Run 9 | K2: Run 10 | L2: Average
A3: 0 | B3: ='[1]GABM_R03_Terry_no_fb-data'!$D2 -> 2 | C3: ='[2]GABM_R03_MitchellAPI_no_fb-data'!$D2 -> 2 | D3: ='[3]GABM_R03_NavidAPI_no_fb-data'!$D2 -> 2 | E3: ='[4]GABM_R03_RandiAPI_no_fb_runtwo-'!$D2 -> 2 | F3: ='[5]GABM_R03_SudipaAPI_no_fb-data'!$D2 -> 2 | G3: ='[6]GABM_R03_NavidAPI_no_fb_runtwo-'!$D2 -> 2 | H3: ='[7]GABM_R03_savannah_no_fb-data'!$D2 -> 2 | I3: ='[8]GABM_R03_Terry_no_fb_run_two-da'!$D2 -> 2 | J3: =[9]GABM_R03_MitchellAPI_no_fb_runt!$D2 -> 2 | K3: ='[10]R03_GABM_NiyoushaAPI_no_fb-data'!$D2 -> 2 | L3: =AVERAGE(B3:K3) -> 2
A4: 1 | B4: ='[1]GABM_R03_Terry_no_fb-data'!$D3 -> 6 | C4: ='[2]GABM_R03_MitchellAPI_no_fb-data'!$D3 -> 4 | D4: ='[3]GABM_R03_NavidAPI_no_fb-data'!$D3 -> 4 | E4: ='[4]GABM_R03_RandiAPI_no_fb_runtwo-'!$D3 -> 2 | F4: ='[5]GABM_R03_SudipaAPI_no_fb-data'!$D3 -> 4 | G4: ='[6]GABM_R03_NavidAPI_no_fb_runtwo-'!$D3 -> 7 | H4: ='[7]GABM_R03_savannah_no_fb-data'!$D3 -> 2 | I4: ='[8]GABM_R03_Terry_no_fb_run_two-da'!$D3 -> 4 | J4: =[9]GABM_R03_MitchellAPI_no_fb_runt!$D3 -> 3 | K4: ='[10]R03_GABM_NiyoushaAPI_no_fb-data'!$D3 -> 5 | L4: =AVERAGE(B4:K4) -> 4.1
A5: 2 | B5: ='[1]GABM_R03_Terry_no_fb-data'!$D4 -> 9 | C5: ='[2]GABM_R03_MitchellAPI_no_fb-data'!$D4 -> 8 | D5: ='[3]GABM_R03_NavidAPI_no_fb-data'!$D4 -> 7 | E5: ='[4]GABM_R03_RandiAPI_no_fb_runtwo-'!$D4 -> 6 | F5: ='[5]GABM_R03_SudipaAPI_no_fb-data'!$D4 -> 7 | G5: ='[6]GABM_R03_NavidAPI_no_fb_runtwo-'!$D4 -> 13 | H5: ='[7]GABM_R03_savannah_no_fb-data'!$D4 -> 6 | I5: ='[8]GABM_R03_Terry_no_fb_run_two-da'!$D4 -> 6 | J5: =[9]GABM_R03_MitchellAPI_no_fb_runt!$D4 -> 4 | K5: ='[10]R03_GABM_NiyoushaAPI_no_fb-data'!$D4 -> 12 | L5: =AVERAGE(B5:K5) -> 7.8
A6: 3 | B6: ='[1]GABM_R03_Terry_no_fb-data'!$D5 -> 15 | C6: ='[2]GABM_R03_MitchellAPI_no_fb-data'!$D5 -> 15 | D6: ='[3]GABM_R03_NavidAPI_no_fb-data'!$D5 -> 12 | E6: ='[4]GABM_R03_RandiAPI_no_fb_runtwo-'!$D5 -> 13 | F6: ='[5]GABM_R03_SudipaAPI_no_fb-data'!$D5 -> 15 | G6: ='[6]GABM_R03_NavidAPI_no_fb_runtwo-'!$D5 -> 25 | H6: ='[7]GABM_R03_savannah_no_fb-data'!$D5 -> 14 | I6: ='[8]GABM_R03_Terry_no_fb_run_two-da'!$D5 -> 12 | J6: =[9]GABM_R03_MitchellAPI_no_fb_runt!$D5 -> 10 | K6: ='[10]R03_GABM_NiyoushaAPI_no_fb-data'!$D5 -> 19 | L6: =AVERAGE(B6:K6) -> 15
A7: 4 | B7: ='[1]GABM_R03_Terry_no_fb-data'!$D6 -> 40 | C7: ='[2]GABM_R03_MitchellAPI_no_fb-data'!$D6 -> 24 | D7: ='[3]GABM_R03_NavidAPI_no_fb-data'!$D6 -> 21 | E7: ='[4]GABM_R03_RandiAPI_no_fb_runtwo-'!$D6 -> 26 | F7: ='[5]GABM_R03_SudipaAPI_no_fb-data'!$D6 -> 33 | G7: ='[6]GABM_R03_NavidAPI_no_fb_runtwo-'!$D6 -> 47 | H7: ='[7]GABM_R03_savannah_no_fb-data'!$D6 -> 27 | I7: ='[8]GABM_R03_Terry_no_fb_run_two-da'!$D6 -> 24 | J7: =[9]GABM_R03_MitchellAPI_no_fb_runt!$D6 -> 17 | K7: ='[10]R03_GABM_NiyoushaAPI_no_fb-data'!$D6 -> 44 | L7: =AVERAGE(B7:K7) -> 30.3
A8: 5 | B8: ='[1]GABM_R03_Terry_no_fb-data'!$D7 -> 78 | C8: ='[2]GABM_R03_MitchellAPI_no_fb-data'!$D7 -> 58 | D8: ='[3]GABM_R03_NavidAPI_no_fb-data'!$D7 -> 43 | E8: ='[4]GABM_R03_RandiAPI_no_fb_runtwo-'!$D7 -> 42 | F8: ='[5]GABM_R03_SudipaAPI_no_fb-data'!$D7 -> 60 | G8: ='[6]GABM_R03_NavidAPI_no_fb_runtwo-'!$D7 -> 92 | H8: ='[7]GABM_R03_savannah_no_fb-data'!$D7 -> 52 | I8: ='[8]GABM_R03_Terry_no_fb_run_two-da'!$D7 -> 38 | J8: =[9]GABM_R03_MitchellAPI_no_fb_runt!$D7 -> 30 | K8: ='[10]R03_GABM_NiyoushaAPI_no_fb-data'!$D7 -> 83 | L8: =AVERAGE(B8:K8) -> 57.6
A9: 6 | B9: ='[1]GABM_R03_Terry_no_fb-data'!$D8 -> 146 | C9: ='[2]GABM_R03_MitchellAPI_no_fb-data'!$D8 -> 121 | D9: ='[3]GABM_R03_NavidAPI_no_fb-data'!$D8 -> 73 | E9: ='[4]GABM_R03_RandiAPI_no_fb_runtwo-'!$D8 -> 84 | F9: ='[5]GABM_R03_SudipaAPI_no_fb-data'!$D8 -> 121 | G9: ='[6]GABM_R03_NavidAPI_no_fb_runtwo-'!$D8 -> 166 | H9: ='[7]GABM_R03_savannah_no_fb-data'!$D8 -> 87 | I9: ='[8]GABM_R03_Terry_no_fb_run_two-da'!$D8 -> 80 | J9: =[9]GABM_R03_MitchellAPI_no_fb_runt!$D8 -> 60 | K9: ='[10]R03_GABM_NiyoushaAPI_no_fb-data'!$D8 -> 164 | L9: =AVERAGE(B9:K9) -> 110.2
A10: 7 | B10: ='[1]GABM_R03_Terry_no_fb-data'!$D9 -> 234 | C10: ='[2]GABM_R03_MitchellAPI_no_fb-data'!$D9 -> 212 | D10: ='[3]GABM_R03_NavidAPI_no_fb-data'!$D9 -> 133 | E10: ='[4]GABM_R03_RandiAPI_no_fb_runtwo-'!$D9 -> 146 | F10: ='[5]GABM_R03_SudipaAPI_no_fb-data'!$D9 -> 210 | G10: ='[6]GABM_R03_NavidAPI_no_fb_runtwo-'!$D9 -> 293 | H10: ='[7]GABM_R03_savannah_no_fb-data'!$D9 -> 160 | I10: ='[8]GABM_R03_Terry_no_fb_run_two-da'!$D9 -> 137 | J10: =[9]GABM_R03_MitchellAPI_no_fb_runt!$D9 -> 110 | K10: ='[10]R03_GABM_NiyoushaAPI_no_fb-data'!$D9 -> 289 | L10: =AVERAGE(B10:K10) -> 192.4
A11: 8 | B11: ='[1]GABM_R03_Terry_no_fb-data'!$D10 -> 389 | C11: ='[2]GABM_R03_MitchellAPI_no_fb-data'!$D10 -> 372 | D11: ='[3]GABM_R03_NavidAPI_no_fb-data'!$D10 -> 231 | E11: ='[4]GABM_R03_RandiAPI_no_fb_runtwo-'!$D10 -> 265 | F11: ='[5]GABM_R03_SudipaAPI_no_fb-data'!$D10 -> 363 | G11: ='[6]GABM_R03_NavidAPI_no_fb_runtwo-'!$D10 -> 449 | H11: ='[7]GABM_R03_savannah_no_fb-data'!$D10 -> 275 | I11: ='[8]GABM_R03_Terry_no_fb_run_two-da'!$D10 -> 235 | J11: =[9]GABM_R03_MitchellAPI_no_fb_runt!$D10 -> 185 | K11: ='[10]R03_GABM_NiyoushaAPI_no_fb-data'!$D10 -> 448 | L11: =AVERAGE(B11:K11) -> 321.2
A12: 9 | B12: ='[1]GABM_R03_Terry_no_fb-data'!$D11 -> 581 | C12: ='[2]GABM_R03_MitchellAPI_no_fb-data'!$D11 -> 555 | D12: ='[3]GABM_R03_NavidAPI_no_fb-data'!$D11 -> 390 | E12: ='[4]GABM_R03_RandiAPI_no_fb_runtwo-'!$D11 -> 434 | F12: ='[5]GABM_R03_SudipaAPI_no_fb-data'!$D11 -> 531 | G12: ='[6]GABM_R03_NavidAPI_no_fb_runtwo-'!$D11 -> 615 | H12: ='[7]GABM_R03_savannah_no_fb-data'!$D11 -> 443 | I12: ='[8]GABM_R03_Terry_no_fb_run_two-da'!$D11 -> 384 | J12: =[9]GABM_R03_MitchellAPI_no_fb_runt!$D11 -> 318 | K12: ='[10]R03_GABM_NiyoushaAPI_no_fb-data'!$D11 -> 643 | L12: =AVERAGE(B12:K12) -> 489.4
A13: 10 | B13: ='[1]GABM_R03_Terry_no_fb-data'!$D12 -> 739 | C13: ='[2]GABM_R03_MitchellAPI_no_fb-data'!$D12 -> 732 | D13: ='[3]GABM_R03_NavidAPI_no_fb-data'!$D12 -> 565 | E13: ='[4]GABM_R03_RandiAPI_no_fb_runtwo-'!$D12 -> 599 | F13: ='[5]GABM_R03_SudipaAPI_no_fb-data'!$D12 -> 702 | G13: ='[6]GABM_R03_NavidAPI_no_fb_runtwo-'!$D12 -> 757 | H13: ='[7]GABM_R03_savannah_no_fb-data'!$D12 -> 625 | I13: ='[8]GABM_R03_Terry_no_fb_run_two-da'!$D12 -> 556 | J13: =[9]GABM_R03_MitchellAPI_no_fb_runt!$D12 -> 489 | K13: ='[10]R03_GABM_NiyoushaAPI_no_fb-data'!$D12 -> 793 | L13: =AVERAGE(B13:K13) -> 655.7
A14: 11 | B14: ='[1]GABM_R03_Terry_no_fb-data'!$D13 -> 814 | C14: ='[2]GABM_R03_MitchellAPI_no_fb-data'!$D13 -> 829 | D14: ='[3]GABM_R03_NavidAPI_no_fb-data'!$D13 -> 716 | E14: ='[4]GABM_R03_RandiAPI_no_fb_runtwo-'!$D13 -> 748 | F14: ='[5]GABM_R03_SudipaAPI_no_fb-data'!$D13 -> 815 | G14: ='[6]GABM_R03_NavidAPI_no_fb_runtwo-'!$D13 -> 825 | H14: ='[7]GABM_R03_savannah_no_fb-data'!$D13 -> 757 | I14: ='[8]GABM_R03_Terry_no_fb_run_two-da'!$D13 -> 720 | J14: =[9]GABM_R03_MitchellAPI_no_fb_runt!$D13 -> 670 | K14: ='[10]R03_GABM_NiyoushaAPI_no_fb-data'!$D13 -> 856 | L14: =AVERAGE(B14:K14) -> 775
... A25: 22 | B25: ='[1]GABM_R03_Terry_no_fb-data'!$D24 -> 0 | C25: ='[2]GABM_R03_MitchellAPI_no_fb-data'!$D24 -> 1 | D25: ='[3]GABM_R03_NavidAPI_no_fb-data'!$D24 -> 4 | E25: ='[4]GABM_R03_RandiAPI_no_fb_runtwo-'!$D24 -> 1 | F25: ='[5]GABM_R03_SudipaAPI_no_fb-data'!$D24 -> 2 | G25: ='[6]GABM_R03_NavidAPI_no_fb_runtwo-'!$D24 -> 1 | H25: ='[7]GABM_R03_savannah_no_fb-data'!$D24 -> 5 | I25: ='[8]GABM_R03_Terry_no_fb_run_two-da'!$D24 -> 6 | J25: =[9]GABM_R03_MitchellAPI_no_fb_runt!$D24 -> 4 | K25: ='[10]R03_GABM_NiyoushaAPI_no_fb-data'!$D24 -> 0 | L25: =AVERAGE(B25:K25) -> 2.4
A26: 23 | B26: 0 | C26: ='[2]GABM_R03_MitchellAPI_no_fb-data'!$D25 -> 1 | D26: ='[3]GABM_R03_NavidAPI_no_fb-data'!$D25 -> 2 | E26: ='[4]GABM_R03_RandiAPI_no_fb_runtwo-'!$D25 -> 0 | F26: ='[5]GABM_R03_SudipaAPI_no_fb-data'!$D25 -> 1 | G26: ='[6]GABM_R03_NavidAPI_no_fb_runtwo-'!$D25 -> 0 | H26: ='[7]GABM_R03_savannah_no_fb-data'!$D25 -> 1 | I26: ='[8]GABM_R03_Terry_no_fb_run_two-da'!$D25 -> 1 | J26: =[9]GABM_R03_MitchellAPI_no_fb_runt!$D25 -> 2 | K26: 0 | L26: =AVERAGE(B26:K26) -> 0.8
A27: 24 | B27: 0 | C27: ='[2]GABM_R03_MitchellAPI_no_fb-data'!$D26 -> 0 | D27: ='[3]GABM_R03_NavidAPI_no_fb-data'!$D26 -> 2 | E27: 0 | F27: ='[5]GABM_R03_SudipaAPI_no_fb-data'!$D26 -> 1 | G27: 0 | H27: ='[7]GABM_R03_savannah_no_fb-data'!$D26 -> 1 | I27: ='[8]GABM_R03_Terry_no_fb_run_two-da'!$D26 -> 1 | J27: =[9]GABM_R03_MitchellAPI_no_fb_runt!$D26 -> 0 | K27: 0 | L27: =AVERAGE(B27:K27) -> 0.5
A28: 25 | B28: 0 | C28: 0 | D28: ='[3]GABM_R03_NavidAPI_no_fb-data'!$D27 -> 0 | E28: 0 | F28: ='[5]GABM_R03_SudipaAPI_no_fb-data'!$D27 -> 1 | G28: 0 | H28: ='[7]GABM_R03_savannah_no_fb-data'!$D27 -> 0 | I28: ='[8]GABM_R03_Terry_no_fb_run_two-da'!$D27 -> 0 | J28: 0 | K28: 0 | L28: =AVERAGE(B28:K28) -> 0.1
A29: 26 | B29: 0 | C29: 0 | D29: 0 | E29: 0 | F29: ='[5]GABM_R03_SudipaAPI_no_fb-data'!$D28 -> 0 | G29: 0 | H29: 0 | I29: 0 | J29: 0 | K29: 0 | L29: =AVERAGE(B29:K29) -> 0

Sheet Infected SF
A1: Number of Infections per timestep
A2: Time Step | B2: Run 1 | C2: Run 2 | D2: Run 3 | E2: Run 4 | F2: Run 5 | G2: Run 6 | H2: Run 7 | I2: Run 8 | J2: Run 9 | K2: Run 10 | L2: Average
A3: 0 | B3: ='[11]GABM_R03_NavidAPI_sf_fb-data'!$D2 -> 2 | C3: ='[12]GABM_R03_savannah_sf_fb-data'!$D2 -> 2 | D3: ='[13]GABM_R03_MitchellAPI_sf_fb-data'!$D2 -> 2 | E3: ='[14]GABM_R03_RandiAPI_sf_fb-data'!$D2 -> 2 | F3: ='[15]GABM_R03_Terry_sf_fb-data'!$D2 -> 2 | G3: ='[16]R03_GABM_NiyoushaAPI_sf_fb-data'!$D2 -> 2 | H3: ='[17]GABM_R03_SudipaAPI_sf_fb-data'!$D2 -> 2 | I3: ='[18]GABM_R03_Terry_sf_fb_2-data'!$D2 -> 2 | J3: ='[19]GABM_R03_NavidAPI_sf_fb_2-data'!$D2 -> 2 | K3: ='[20]R03_GABM_NiyoushaAPI_sf_fb_2-da'!$D2 -> 2 | L3: =AVERAGE(B3:K3) -> 2
A4: 1 | B4: ='[11]GABM_R03_NavidAPI_sf_fb-data'!$D3 -> 6 | C4: ='[12]GABM_R03_savannah_sf_fb-data'!$D3 -> 4 | D4: ='[13]GABM_R03_MitchellAPI_sf_fb-data'!$D3 -> 4 | E4: ='[14]GABM_R03_RandiAPI_sf_fb-data'!$D3 -> 2 | F4: ='[15]GABM_R03_Terry_sf_fb-data'!$D3 -> 5 | G4: ='[16]R03_GABM_NiyoushaAPI_sf_fb-data'!$D3 -> 4 | H4: ='[17]GABM_R03_SudipaAPI_sf_fb-data'!$D3 -> 3 | I4: ='[18]GABM_R03_Terry_sf_fb_2-data'!$D3 -> 6 | J4: ='[19]GABM_R03_NavidAPI_sf_fb_2-data'!$D3 -> 4 | K4: ='[20]R03_GABM_NiyoushaAPI_sf_fb_2-da'!$D3 -> 2 | L4: =AVERAGE(B4:K4) -> 4
A5: 2 | B5: ='[11]GABM_R03_NavidAPI_sf_fb-data'!$D4 -> 10 | C5: ='[12]GABM_R03_savannah_sf_fb-data'!$D4 -> 12 | D5: ='[13]GABM_R03_MitchellAPI_sf_fb-data'!$D4 -> 7 | E5: ='[14]GABM_R03_RandiAPI_sf_fb-data'!$D4 -> 2 | F5: ='[15]GABM_R03_Terry_sf_fb-data'!$D4 -> 11 | G5: ='[16]R03_GABM_NiyoushaAPI_sf_fb-data'!$D4 -> 9 | H5: ='[17]GABM_R03_SudipaAPI_sf_fb-data'!$D4 -> 6 | I5: ='[18]GABM_R03_Terry_sf_fb_2-data'!$D4 -> 11 | J5: ='[19]GABM_R03_NavidAPI_sf_fb_2-data'!$D4 -> 11 | K5: ='[20]R03_GABM_NiyoushaAPI_sf_fb_2-da'!$D4 -> 6 | L5: =AVERAGE(B5:K5) -> 8.5
A6: 3 | B6: ='[11]GABM_R03_NavidAPI_sf_fb-data'!$D5 -> 21 | C6: ='[12]GABM_R03_savannah_sf_fb-data'!$D5 -> 17 | D6: ='[13]GABM_R03_MitchellAPI_sf_fb-data'!$D5 -> 11 | E6: ='[14]GABM_R03_RandiAPI_sf_fb-data'!$D5 -> 2 | F6: ='[15]GABM_R03_Terry_sf_fb-data'!$D5 -> 18 | G6: ='[16]R03_GABM_NiyoushaAPI_sf_fb-data'!$D5 -> 20 | H6: ='[17]GABM_R03_SudipaAPI_sf_fb-data'!$D5 -> 13 | I6: ='[18]GABM_R03_Terry_sf_fb_2-data'!$D5 -> 22 | J6: ='[19]GABM_R03_NavidAPI_sf_fb_2-data'!$D5 -> 17 | K6: ='[20]R03_GABM_NiyoushaAPI_sf_fb_2-da'!$D5 -> 9 | L6: =AVERAGE(B6:K6) -> 15
A7: 4 | B7: ='[11]GABM_R03_NavidAPI_sf_fb-data'!$D6 -> 37 | C7: ='[12]GABM_R03_savannah_sf_fb-data'!$D6 -> 26 | D7: ='[13]GABM_R03_MitchellAPI_sf_fb-data'!$D6 -> 19 | E7: ='[14]GABM_R03_RandiAPI_sf_fb-data'!$D6 -> 2 | F7: ='[15]GABM_R03_Terry_sf_fb-data'!$D6 -> 25 | G7: ='[16]R03_GABM_NiyoushaAPI_sf_fb-data'!$D6 -> 30 | H7: ='[17]GABM_R03_SudipaAPI_sf_fb-data'!$D6 -> 20 | I7: ='[18]GABM_R03_Terry_sf_fb_2-data'!$D6 -> 38 | J7: ='[19]GABM_R03_NavidAPI_sf_fb_2-data'!$D6 -> 27 | K7: ='[20]R03_GABM_NiyoushaAPI_sf_fb_2-da'!$D6 -> 14 | L7: =AVERAGE(B7:K7) -> 23.8
A8: 5 | B8: ='[11]GABM_R03_NavidAPI_sf_fb-data'!$D7 -> 66 | C8: ='[12]GABM_R03_savannah_sf_fb-data'!$D7 -> 40 | D8: ='[13]GABM_R03_MitchellAPI_sf_fb-data'!$D7 -> 30 | E8: ='[14]GABM_R03_RandiAPI_sf_fb-data'!$D7 -> 2 | F8: ='[15]GABM_R03_Terry_sf_fb-data'!$D7 -> 41 | G8: ='[16]R03_GABM_NiyoushaAPI_sf_fb-data'!$D7 -> 47 | H8: ='[17]GABM_R03_SudipaAPI_sf_fb-data'!$D7 -> 34 | I8: ='[18]GABM_R03_Terry_sf_fb_2-data'!$D7 -> 63 | J8: ='[19]GABM_R03_NavidAPI_sf_fb_2-data'!$D7 -> 41 | K8: ='[20]R03_GABM_NiyoushaAPI_sf_fb_2-da'!$D7 -> 22 | L8: =AVERAGE(B8:K8) -> 38.6
A9: 6 | B9: ='[11]GABM_R03_NavidAPI_sf_fb-data'!$D8 -> 101 | C9: ='[12]GABM_R03_savannah_sf_fb-data'!$D8 -> 53 | D9: ='[13]GABM_R03_MitchellAPI_sf_fb-data'!$D8 -> 47 | E9: ='[14]GABM_R03_RandiAPI_sf_fb-data'!$D8 -> 0 | F9: ='[15]GABM_R03_Terry_sf_fb-data'!$D8 -> 64 | G9: ='[16]R03_GABM_NiyoushaAPI_sf_fb-data'!$D8 -> 71 | H9: ='[17]GABM_R03_SudipaAPI_sf_fb-data'!$D8 -> 56 | I9: ='[18]GABM_R03_Terry_sf_fb_2-data'!$D8 -> 102 | J9: ='[19]GABM_R03_NavidAPI_sf_fb_2-data'!$D8 -> 55 | K9: ='[20]R03_GABM_NiyoushaAPI_sf_fb_2-da'!$D8 -> 32 | L9: =AVERAGE(B9:K9) -> 58.1
A10: 7 | B10: ='[11]GABM_R03_NavidAPI_sf_fb-data'!$D9 -> 154 | C10: ='[12]GABM_R03_savannah_sf_fb-data'!$D9 -> 79 | D10: ='[13]GABM_R03_MitchellAPI_sf_fb-data'!$D9 -> 64 | E10: ='[14]GABM_R03_RandiAPI_sf_fb-data'!$D9 -> 0 | F10: ='[15]GABM_R03_Terry_sf_fb-data'!$D9 -> 101 | G10: ='[16]R03_GABM_NiyoushaAPI_sf_fb-data'!$D9 -> 118 | H10: ='[17]GABM_R03_SudipaAPI_sf_fb-data'!$D9 -> 93 | I10: ='[18]GABM_R03_Terry_sf_fb_2-data'!$D9 -> 159 | J10: ='[19]GABM_R03_NavidAPI_sf_fb_2-data'!$D9 -> 84 | K10: ='[20]R03_GABM_NiyoushaAPI_sf_fb_2-da'!$D9 -> 45 | L10: =AVERAGE(B10:K10) -> 89.7
A11: 8 | B11: ='[11]GABM_R03_NavidAPI_sf_fb-data'!$D10 -> 212 | C11: ='[12]GABM_R03_savannah_sf_fb-data'!$D10 -> 107 | D11: ='[13]GABM_R03_MitchellAPI_sf_fb-data'!$D10 -> 94 | E11: ='[14]GABM_R03_RandiAPI_sf_fb-data'!$D10 -> 0 | F11: ='[15]GABM_R03_Terry_sf_fb-data'!$D10 -> 155 | G11: ='[16]R03_GABM_NiyoushaAPI_sf_fb-data'!$D10 -> 169 | H11: ='[17]GABM_R03_SudipaAPI_sf_fb-data'!$D10 -> 136 | I11: ='[18]GABM_R03_Terry_sf_fb_2-data'!$D10 -> 231 | J11: ='[19]GABM_R03_NavidAPI_sf_fb_2-data'!$D10 -> 109 | K11: ='[20]R03_GABM_NiyoushaAPI_sf_fb_2-da'!$D10 -> 66 | L11: =AVERAGE(B11:K11) -> 127.9
A12: 9 | B12: ='[11]GABM_R03_NavidAPI_sf_fb-data'!$D11 -> 273 | C12: ='[12]GABM_R03_savannah_sf_fb-data'!$D11 -> 152 | D12: ='[13]GABM_R03_MitchellAPI_sf_fb-data'!$D11 -> 132 | E12: ='[14]GABM_R03_RandiAPI_sf_fb-data'!$D11 -> 0 | F12: ='[15]GABM_R03_Terry_sf_fb-data'!$D11 -> 219 | G12: ='[16]R03_GABM_NiyoushaAPI_sf_fb-data'!$D11 -> 241 | H12: ='[17]GABM_R03_SudipaAPI_sf_fb-data'!$D11 -> 200 | I12: ='[18]GABM_R03_Terry_sf_fb_2-data'!$D11 -> 315 | J12: ='[19]GABM_R03_NavidAPI_sf_fb_2-data'!$D11 -> 157 | K12: ='[20]R03_GABM_NiyoushaAPI_sf_fb_2-da'!$D11 -> 97 | L12: =AVERAGE(B12:K12) -> 178.6
A13: 10 | B13: ='[11]GABM_R03_NavidAPI_sf_fb-data'!$D12 -> 344 | C13: ='[12]GABM_R03_savannah_sf_fb-data'!$D12 -> 208 | D13: ='[13]GABM_R03_MitchellAPI_sf_fb-data'!$D12 -> 183 | E13: ='[14]GABM_R03_RandiAPI_sf_fb-data'!$D12 -> 0 | F13: ='[15]GABM_R03_Terry_sf_fb-data'!$D12 -> 316 | G13: ='[16]R03_GABM_NiyoushaAPI_sf_fb-data'!$D12 -> 316 | H13: ='[17]GABM_R03_SudipaAPI_sf_fb-data'!$D12 -> 269 | I13: ='[18]GABM_R03_Terry_sf_fb_2-data'!$D12 -> 392 | J13: ='[19]GABM_R03_NavidAPI_sf_fb_2-data'!$D12 -> 214 | K13: ='[20]R03_GABM_NiyoushaAPI_sf_fb_2-da'!$D12 -> 131 | L13: =AVERAGE(B13:K13) -> 237.3
A14: 11 | B14: ='[11]GABM_R03_NavidAPI_sf_fb-data'!$D13 -> 397 | C14: ='[12]GABM_R03_savannah_sf_fb-data'!$D13 -> 269 | D14: ='[13]GABM_R03_MitchellAPI_sf_fb-data'!$D13 -> 231 | E14: ='[14]GABM_R03_RandiAPI_sf_fb-data'!$D13 -> 0 | F14: ='[15]GABM_R03_Terry_sf_fb-data'!$D13 -> 399 | G14: ='[16]R03_GABM_NiyoushaAPI_sf_fb-data'!$D13 -> 413 | H14: ='[17]GABM_R03_SudipaAPI_sf_fb-data'!$D13 -> 348 | I14: ='[18]GABM_R03_Terry_sf_fb_2-data'!$D13 -> 466 | J14: ='[19]GABM_R03_NavidAPI_sf_fb_2-data'!$D13 -> 278 | K14: ='[20]R03_GABM_NiyoushaAPI_sf_fb_2-da'!$D13 -> 182 | L14: =AVERAGE(B14:K14) -> 298.3
... A37: 34 | B37: ='[11]GABM_R03_NavidAPI_sf_fb-data'!$D36 -> 0 | C37: ='[12]GABM_R03_savannah_sf_fb-data'!$D36 -> 0 | D37: ='[13]GABM_R03_MitchellAPI_sf_fb-data'!$D36 -> 0 | E37: ='[14]GABM_R03_RandiAPI_sf_fb-data'!$D36 -> 0 | F37: ='[15]GABM_R03_Terry_sf_fb-data'!$D36 -> 0 | G37: ='[16]R03_GABM_NiyoushaAPI_sf_fb-data'!$D36 -> 0 | H37: ='[17]GABM_R03_SudipaAPI_sf_fb-data'!$D36 -> 0 | I37: ='[18]GABM_R03_Terry_sf_fb_2-data'!$D36 -> 0 | J37: ='[19]GABM_R03_NavidAPI_sf_fb_2-data'!$D36 -> 0 | K37: ='[20]R03_GABM_NiyoushaAPI_sf_fb_2-da'!$D36 -> 0 | L37: =AVERAGE(B37:K37) -> 0

Sheet Infected FF
A1: Number of Infections per timestep
A2: Time Step | B2: Run 1 | C2: Run 2 | D2: Run 3 | E2: Run 4 | F2: Run 5 | G2: Run 6 | H2: Run 7 | I2: Run 8 | J2: Run 9 | K2: Run 10 | L2: Average
A3: 0 | B3: ='[21]R03_GABM-data'!$D2 -> 2 | C3: ='[22]GABM_R03_RossAPI-data'!$D2 -> 2 | D3: ='[23]GABM_R03_RandiAPI-data'!$D2 -> 2 | E3: ='[24]GABM_R03_NavidAPI-data'!$D2 -> 2 | F3: ='[25]GABM_R03_Terry-data'!$D2 -> 2 | G3: ='[26]GABM_R03_SarahAPI-data'!$D2 -> 2 | H3: ='[27]GABM_R03_savannah-data'!$D2 -> 2 | I3: ='[28]GABM_R03_MitchellAPI-data'!$D2 -> 2 | J3: ='[29]GABM_R03_SudipaAPI-data'!$D2 -> 2 | K3: ='[30]R03_GABM_run2-data'!$D2 -> 2 | L3: =AVERAGE(B3:K3) -> 2
A4: 1 | B4: ='[21]R03_GABM-data'!$D3 -> 5 | C4: ='[22]GABM_R03_RossAPI-data'!$D3 -> 3 | D4: ='[23]GABM_R03_RandiAPI-data'!$D3 -> 6 | E4: ='[24]GABM_R03_NavidAPI-data'!$D3 -> 2 | F4: ='[25]GABM_R03_Terry-data'!$D3 -> 4 | G4: ='[26]GABM_R03_SarahAPI-data'!$D3 -> 2 | H4: ='[27]GABM_R03_savannah-data'!$D3 -> 3 | I4: ='[28]GABM_R03_MitchellAPI-data'!$D3 -> 5 | J4: ='[29]GABM_R03_SudipaAPI-data'!$D3 -> 5 | K4: ='[30]R03_GABM_run2-data'!$D3 -> 7 | L4: =AVERAGE(B4:K4) -> 4.2
A5: 2 | B5: ='[21]R03_GABM-data'!$D4 -> 14 | C5: ='[22]GABM_R03_RossAPI-data'!$D4 -> 7 | D5: ='[23]GABM_R03_RandiAPI-data'!$D4 -> 11 | E5: ='[24]GABM_R03_NavidAPI-data'!$D4 -> 5 | F5: ='[25]GABM_R03_Terry-data'!$D4 -> 9 | G5: ='[26]GABM_R03_SarahAPI-data'!$D4 -> 4 | H5: ='[27]GABM_R03_savannah-data'!$D4 -> 5 | I5: ='[28]GABM_R03_MitchellAPI-data'!$D4 -> 12 | J5: ='[29]GABM_R03_SudipaAPI-data'!$D4 -> 7 | K5: ='[30]R03_GABM_run2-data'!$D4 -> 10 | L5: =AVERAGE(B5:K5) -> 8.4
A6: 3 | B6: ='[21]R03_GABM-data'!$D5 -> 22 | C6: ='[22]GABM_R03_RossAPI-data'!$D5 -> 17 | D6: ='[23]GABM_R03_RandiAPI-data'!$D5 -> 20 | E6: ='[24]GABM_R03_NavidAPI-data'!$D5 -> 13 | F6: ='[25]GABM_R03_Terry-data'!$D5 -> 15 | G6: ='[26]GABM_R03_SarahAPI-data'!$D5 -> 6 | H6: ='[27]GABM_R03_savannah-data'!$D5 -> 10 | I6: ='[28]GABM_R03_MitchellAPI-data'!$D5 -> 23 | J6: ='[29]GABM_R03_SudipaAPI-data'!$D5 -> 12 | K6: ='[30]R03_GABM_run2-data'!$D5 -> 15 | L6: =AVERAGE(B6:K6) -> 15.3
A7: 4 | B7: ='[21]R03_GABM-data'!$D6 -> 35 | C7: ='[22]GABM_R03_RossAPI-data'!$D6 -> 33 | D7: ='[23]GABM_R03_RandiAPI-data'!$D6 -> 27 | E7: ='[24]GABM_R03_NavidAPI-data'!$D6 -> 20 | F7: ='[25]GABM_R03_Terry-data'!$D6 -> 23 | G7: ='[26]GABM_R03_SarahAPI-data'!$D6 -> 9 | H7: ='[27]GABM_R03_savannah-data'!$D6 -> 14 | I7: ='[28]GABM_R03_MitchellAPI-data'!$D6 -> 31 | J7: ='[29]GABM_R03_SudipaAPI-data'!$D6 -> 13 | K7: ='[30]R03_GABM_run2-data'!$D6 -> 20 | L7: =AVERAGE(B7:K7) -> 22.5
A8: 5 | B8: ='[21]R03_GABM-data'!$D7 -> 50 | C8: ='[22]GABM_R03_RossAPI-data'!$D7 -> 48 | D8: ='[23]GABM_R03_RandiAPI-data'!$D7 -> 34 | E8: ='[24]GABM_R03_NavidAPI-data'!$D7 -> 39 | F8: ='[25]GABM_R03_Terry-data'!$D7 -> 33 | G8: ='[26]GABM_R03_SarahAPI-data'!$D7 -> 17 | H8: ='[27]GABM_R03_savannah-data'!$D7 -> 16 | I8: ='[28]GABM_R03_MitchellAPI-data'!$D7 -> 44 | J8: ='[29]GABM_R03_SudipaAPI-data'!$D7 -> 17 | K8: ='[30]R03_GABM_run2-data'!$D7 -> 22 | L8: =AVERAGE(B8:K8) -> 32
A9: 6 | B9: ='[21]R03_GABM-data'!$D8 -> 68 | C9: ='[22]GABM_R03_RossAPI-data'!$D8 -> 64 | D9: ='[23]GABM_R03_RandiAPI-data'!$D8 -> 38 | E9: ='[24]GABM_R03_NavidAPI-data'!$D8 -> 52 | F9: ='[25]GABM_R03_Terry-data'!$D8 -> 41 | G9: ='[26]GABM_R03_SarahAPI-data'!$D8 -> 19 | H9: ='[27]GABM_R03_savannah-data'!$D8 -> 19 | I9: ='[28]GABM_R03_MitchellAPI-data'!$D8 -> 56 | J9: ='[29]GABM_R03_SudipaAPI-data'!$D8 -> 18 | K9: ='[30]R03_GABM_run2-data'!$D8 -> 24 | L9: =AVERAGE(B9:K9) -> 39.9
A10: 7 | B10: ='[21]R03_GABM-data'!$D9 -> 81 | C10: ='[22]GABM_R03_RossAPI-data'!$D9 -> 89 | D10: ='[23]GABM_R03_RandiAPI-data'!$D9 -> 46 | E10: ='[24]GABM_R03_NavidAPI-data'!$D9 -> 67 | F10: ='[25]GABM_R03_Terry-data'!$D9 -> 48 | G10: ='[26]GABM_R03_SarahAPI-data'!$D9 -> 29 | H10: ='[27]GABM_R03_savannah-data'!$D9 -> 20 | I10: ='[28]GABM_R03_MitchellAPI-data'!$D9 -> 67 | J10: ='[29]GABM_R03_SudipaAPI-data'!$D9 -> 18 | K10: ='[30]R03_GABM_run2-data'!$D9 -> 21 | L10: =AVERAGE(B10:K10) -> 48.6
A11: 8 | B11: ='[21]R03_GABM-data'!$D10 -> 85 | C11: ='[22]GABM_R03_RossAPI-data'!$D10 -> 92 | D11: ='[23]GABM_R03_RandiAPI-data'!$D10 -> 52 | E11: ='[24]GABM_R03_NavidAPI-data'!$D10 -> 84 | F11: ='[25]GABM_R03_Terry-data'!$D10 -> 58 | G11: ='[26]GABM_R03_SarahAPI-data'!$D10 -> 39 | H11: ='[27]GABM_R03_savannah-data'!$D10 -> 25 | I11: ='[28]GABM_R03_MitchellAPI-data'!$D10 -> 67 | J11: ='[29]GABM_R03_SudipaAPI-data'!$D10 -> 19 | K11: ='[30]R03_GABM_run2-data'!$D10 -> 22 | L11: =AVERAGE(B11:K11) -> 54.3
A12: 9 | B12: ='[21]R03_GABM-data'!$D11 -> 82 | C12: ='[22]GABM_R03_RossAPI-data'!$D11 -> 86 | D12: ='[23]GABM_R03_RandiAPI-data'!$D11 -> 61 | E12: ='[24]GABM_R03_NavidAPI-data'!$D11 -> 90 | F12: ='[25]GABM_R03_Terry-data'!$D11 -> 69 | G12: ='[26]GABM_R03_SarahAPI-data'!$D11 -> 51 | H12: ='[27]GABM_R03_savannah-data'!$D11 -> 26 | I12: ='[28]GABM_R03_MitchellAPI-data'!$D11 -> 64 | J12: ='[29]GABM_R03_SudipaAPI-data'!$D11 -> 16 | K12: ='[30]R03_GABM_run2-data'!$D11 -> 21 | L12: =AVERAGE(B12:K12) -> 56.6
A13: 10 | B13: ='[21]R03_GABM-data'!$D12 -> 74 | C13: ='[22]GABM_R03_RossAPI-data'!$D12 -> 74 | D13: ='[23]GABM_R03_RandiAPI-data'!$D12 -> 71 | E13: ='[24]GABM_R03_NavidAPI-data'!$D12 -> 89 | F13: ='[25]GABM_R03_Terry-data'!$D12 -> 95 | G13: ='[26]GABM_R03_SarahAPI-data'!$D12 -> 68 | H13: ='[27]GABM_R03_savannah-data'!$D12 -> 29 | I13: ='[28]GABM_R03_MitchellAPI-data'!$D12 -> 61 | J13: ='[29]GABM_R03_SudipaAPI-data'!$D12 -> 21 | K13: ='[30]R03_GABM_run2-data'!$D12 -> 21 | L13: =AVERAGE(B13:K13) -> 60.3
A14: 11 | B14: ='[21]R03_GABM-data'!$D13 -> 63 | C14: ='[22]GABM_R03_RossAPI-data'!$D13 -> 61 | D14: ='[23]GABM_R03_RandiAPI-data'!$D13 -> 70 | E14: ='[24]GABM_R03_NavidAPI-data'!$D13 -> 73 | F14: ='[25]GABM_R03_Terry-data'!$D13 -> 112 | G14: ='[26]GABM_R03_SarahAPI-data'!$D13 -> 89 | H14: ='[27]GABM_R03_savannah-data'!$D13 -> 31 | I14: ='[28]GABM_R03_MitchellAPI-data'!$D13 -> 54 | J14: ='[29]GABM_R03_SudipaAPI-data'!$D13 -> 22 | K14: ='[30]R03_GABM_run2-data'!$D13 -> 26 | L14: =AVERAGE(B14:K14) -> 60.1
... A200: 197 | B200: ='[21]R03_GABM-data'!$D199 -> 0 | C200: ='[22]GABM_R03_RossAPI-data'!$D199 -> 0 | D200: ='[23]GABM_R03_RandiAPI-data'!$D199 -> 0 | E200: ='[24]GABM_R03_NavidAPI-data'!$D199 -> 0 | F200: ='[25]GABM_R03_Terry-data'!$D199 -> 0 | G200: ='[26]GABM_R03_SarahAPI-data'!$D199 -> 0 | H200: ='[27]GABM_R03_savannah-data'!$D199 -> 0 | I200: ='[28]GABM_R03_MitchellAPI-data'!$D199 -> 0 | J200: ='[29]GABM_R03_SudipaAPI-data'!$D199 -> 0 | K200: ='[30]R03_GABM_run2-data'!$D199 -> 0 | L200: =AVERAGE(B200:K200) -> 0

Sheet Mobility NF
A1: Mobility per timestep
A2: Time Step | B2: Run 1 | C2: Run 2 | D2: Run 3 | E2: Run 4 | F2: Run 5 | G2: Run 6 | H2: Run 7 | I2: Run 8 | J2: Run 9 | K2: Run 10 | L2: Average
A3: 0 | B3: 1 | C3: 1 | D3: 1 | E3: 1 | F3: 1 | G3: 1 | H3: 1 | I3: 1 | J3: 1 | K3: 1 | L3: =AVERAGE(B3:K3) -> 1
A4: 1 | B4: ='[1]GABM_R03_Terry_no_fb-data'!$J3/'[1]GABM_R03_Terry_no_fb-data'!$L3 -> 0.9996 | C4: ='[2]GABM_R03_MitchellAPI_no_fb-data'!$J3/'[2]GABM_R03_MitchellAPI_no_fb-data'!$L3 -> 1 | D4: ='[3]GABM_R03_NavidAPI_no_fb-data'!$J3/'[3]GABM_R03_NavidAPI_no_fb-data'!$L3 -> 0.998 | E4: ='[4]GABM_R03_RandiAPI_no_fb_runtwo-'!$J3/'[4]GABM_R03_RandiAPI_no_fb_runtwo-'!$L3 -> 0.998 | F4: ='[5]GABM_R03_SudipaAPI_no_fb-data'!$J3/'[5]GABM_R03_SudipaAPI_no_fb-data'!$L3 -> 0.9972 | G4: ='[6]GABM_R03_NavidAPI_no_fb_runtwo-'!$J3/'[6]GABM_R03_NavidAPI_no_fb_runtwo-'!$L3 -> 1 | H4: ='[7]GABM_R03_savannah_no_fb-data'!$J3/'[7]GABM_R03_savannah_no_fb-data'!$L3 -> 0.9996 | I4: ='[8]GABM_R03_Terry_no_fb_run_two-da'!$J3/'[8]GABM_R03_Terry_no_fb_run_two-da'!$L3 -> 0.9956 | J4: =[9]GABM_R03_MitchellAPI_no_fb_runt!$J3/[9]GABM_R03_MitchellAPI_no_fb_runt!$L3 -> 1 | K4: ='[10]R03_GABM_NiyoushaAPI_no_fb-data'!$J3/'[10]R03_GABM_NiyoushaAPI_no_fb-data'!$L3 -> 0.9992 | L4: =AVERAGE(B4:K4) -> 0.99872
